2019/07/03 08:18:08 [error] 2503#2503: *4 connect() failed (111: Connection refused) while connecting to upstream, client: 127.0.0.1, server: task.local.frontend, request: "GET /index.php?r=site%2Flogin HTTP/1.1", upstream: "fastcgi://127.0.0.1:9000", host: "task.local.frontend"
2019/07/03 08:18:22 [error] 2503#2503: *4 connect() failed (111: Connection refused) while connecting to upstream, client: 127.0.0.1, server: task.local.frontend, request: "GET / HTTP/1.1", upstream: "fastcgi://127.0.0.1:9000", host: "task.local.frontend"
2019/07/03 08:19:55 [error] 2532#2532: *1 connect() failed (111: Connection refused) while connecting to upstream, client: 127.0.0.1, server: task.local.frontend, request: "GET / HTTP/1.1", upstream: "fastcgi://127.0.0.1:9000", host: "task.local.frontend"
2019/07/03 17:54:22 [error] 991#991: *98 FastCGI sent in stderr: "PHP message: An Error occurred while handling another error:
yii\base\InvalidRouteException: Unable to resolve the request "site/error". in /var/www/task.local/vendor/yiisoft/yii2/base/Module.php:537
Stack trace:
#0 /var/www/task.local/vendor/yiisoft/yii2/web/ErrorHandler.php(108): yii\base\Module->runAction('site/error')
#1 /var/www/task.local/vendor/yiisoft/yii2/base/ErrorHandler.php(111): yii\web\ErrorHandler->renderException(Object(yii\web\NotFoundHttpException))
#2 [internal function]: yii\base\ErrorHandler->handleException(Object(yii\web\NotFoundHttpException))
#3 {main}
Previous exception:
yii\base\InvalidRouteException: Unable to resolve the request "site/index". in /var/www/task.local/vendor/yiisoft/yii2/base/Module.php:537
Stack trace:
#0 /var/www/task.local/vendor/yiisoft/yii2/web/Application.php(103): yii\base\Module->runAction('site/index', Array)
#1 /var/www/task.local/vendor/yiisoft/yii2/base/Application.php(386): yii\web\Application->handleRequest(Object(yii\web\Request))
#2 /var/www/task" while reading upstream, client: 127.0.0.1, server: task.local.frontend, request: "GET /site/index HTTP/1.1", upstream: "fastcgi://unix:/var/run/php/php7.2-fpm.sock:", host: "task.local.frontend", referrer: "http://task.local.frontend/"
2019/07/03 17:54:34 [error] 991#991: *98 FastCGI sent in stderr: "PHP message: An Error occurred while handling another error:
yii\base\InvalidRouteException: Unable to resolve the request "site/error". in /var/www/task.local/vendor/yiisoft/yii2/base/Module.php:537
Stack trace:
#0 /var/www/task.local/vendor/yiisoft/yii2/web/ErrorHandler.php(108): yii\base\Module->runAction('site/error')
#1 /var/www/task.local/vendor/yiisoft/yii2/base/ErrorHandler.php(111): yii\web\ErrorHandler->renderException(Object(yii\web\NotFoundHttpException))
#2 [internal function]: yii\base\ErrorHandler->handleException(Object(yii\web\NotFoundHttpException))
#3 {main}
Previous exception:
yii\base\InvalidRouteException: Unable to resolve the request "site/signup". in /var/www/task.local/vendor/yiisoft/yii2/base/Module.php:537
Stack trace:
#0 /var/www/task.local/vendor/yiisoft/yii2/web/Application.php(103): yii\base\Module->runAction('site/signup', Array)
#1 /var/www/task.local/vendor/yiisoft/yii2/base/Application.php(386): yii\web\Application->handleRequest(Object(yii\web\Request))
#2 /var/www/tas" while reading upstream, client: 127.0.0.1, server: task.local.frontend, request: "GET /site/signup HTTP/1.1", upstream: "fastcgi://unix:/var/run/php/php7.2-fpm.sock:", host: "task.local.frontend", referrer: "http://task.local.frontend/"
2019/07/03 18:47:41 [error] 991#991: *108 FastCGI sent in stderr: "PHP message: PHP Fatal error:  Class 'frontend\controllers\Contoller' not found in /var/www/task.local/frontend/controllers/SiteController.php on line 9" while reading response header from upstream, client: 127.0.0.1, server: task.local.frontend, request: "GET / HTTP/1.1", upstream: "fastcgi://unix:/var/run/php/php7.2-fpm.sock:", host: "task.local.frontend"
2019/07/03 18:55:24 [error] 991#991: *118 FastCGI sent in stderr: "PHP message: PHP Fatal error:  Cannot redeclare frontend\controllers\UserController::actionIndex() in /var/www/task.local/frontend/controllers/UserController.php on line 104" while reading response header from upstream, client: 127.0.0.1, server: task.local.frontend, request: "GET /login?error=%D0%92%D1%8B+%D0%BD%D0%B5%D0%B0%D0%B2%D1%82%D0%BE%D1%80%D0%B8%D0%B7%D0%B8%D1%80%D0%BE%D0%B2%D0%B0%D0%BD%D1%8B HTTP/1.1", upstream: "fastcgi://unix:/var/run/php/php7.2-fpm.sock:", host: "task.local.frontend"
2019/07/03 18:58:20 [error] 991#991: *122 FastCGI sent in stderr: "PHP message: PHP Fatal error:  Cannot redeclare frontend\controllers\UserController::actionIndex() in /var/www/task.local/frontend/controllers/UserController.php on line 104" while reading response header from upstream, client: 127.0.0.1, server: task.local.frontend, request: "GET /login?error=%D0%92%D1%8B+%D0%BD%D0%B5%D0%B0%D0%B2%D1%82%D0%BE%D1%80%D0%B8%D0%B7%D0%B8%D1%80%D0%BE%D0%B2%D0%B0%D0%BD%D1%8B HTTP/1.1", upstream: "fastcgi://unix:/var/run/php/php7.2-fpm.sock:", host: "task.local.frontend"
2019/07/03 18:58:22 [error] 991#991: *122 FastCGI sent in stderr: "PHP message: PHP Fatal error:  Cannot redeclare frontend\controllers\UserController::actionIndex() in /var/www/task.local/frontend/controllers/UserController.php on line 104" while reading response header from upstream, client: 127.0.0.1, server: task.local.frontend, request: "GET /login?error=%D0%92%D1%8B+%D0%BD%D0%B5%D0%B0%D0%B2%D1%82%D0%BE%D1%80%D0%B8%D0%B7%D0%B8%D1%80%D0%BE%D0%B2%D0%B0%D0%BD%D1%8B HTTP/1.1", upstream: "fastcgi://unix:/var/run/php/php7.2-fpm.sock:", host: "task.local.frontend"
2019/07/03 19:00:52 [error] 991#991: *125 FastCGI sent in stderr: "PHP message: PHP Warning:  Uncaught yii\base\ErrorException: require_once(./views/login/index.php): failed to open stream: No such file or directory in /var/www/task.local/frontend/controllers/UserController.php:47
Stack trace:
#0 /var/www/task.local/frontend/controllers/UserController.php(47): yii\base\ErrorHandler->handleError(2, 'require_once(./...', '/var/www/task.l...', 47, Array)
#1 /var/www/task.local/frontend/controllers/UserController.php(47): require_once()
#2 [internal function]: frontend\controllers\UserController->actionLogin()
#3 /var/www/task.local/vendor/yiisoft/yii2/base/InlineAction.php(57): call_user_func_array(Array, Array)
#4 /var/www/task.local/vendor/yiisoft/yii2/base/Controller.php(157): yii\base\InlineAction->runWithParams(Array)
#5 /var/www/task.local/vendor/yiisoft/yii2/base/Module.php(528): yii\base\Controller->runAction('login', Array)
#6 /var/www/task.local/vendor/yiisoft/yii2/web/Application.php(103): yii\base\Module->runAction('user/login', Array)
#7 /var/www/task.local/ven...
PHP message: PHP Fatal error:  frontend\controllers\UserController::actionLogin(): Failed opening required './views/login/index.php' (include_path='.:/usr/share/php') in /var/www/task.local/frontend/controllers/UserController.php on line 47" while reading response header from upstream, client: 127.0.0.1, server: task.local.frontend, request: "GET /login?error=%D0%92%D1%8B+%D0%BD%D0%B5%D0%B0%D0%B2%D1%82%D0%BE%D1%80%D0%B8%D0%B7%D0%B8%D1%80%D0%BE%D0%B2%D0%B0%D0%BD%D1%8B HTTP/1.1", upstream: "fastcgi://unix:/var/run/php/php7.2-fpm.sock:", host: "task.local.frontend"
2019/07/03 19:08:51 [error] 991#991: *132 FastCGI sent in stderr: "PHP message: An Error occurred while handling another error:
yii\base\InvalidRouteException: Unable to resolve the request: site/error in /var/www/task.local/vendor/yiisoft/yii2/base/Controller.php:128
Stack trace:
#0 /var/www/task.local/vendor/yiisoft/yii2/base/Module.php(528): yii\base\Controller->runAction('error', Array)
#1 /var/www/task.local/vendor/yiisoft/yii2/web/ErrorHandler.php(108): yii\base\Module->runAction('site/error')
#2 /var/www/task.local/vendor/yiisoft/yii2/base/ErrorHandler.php(111): yii\web\ErrorHandler->renderException(Object(yii\web\NotFoundHttpException))
#3 [internal function]: yii\base\ErrorHandler->handleException(Object(yii\web\NotFoundHttpException))
#4 {main}
Previous exception:
yii\base\InvalidRouteException: Unable to resolve the request "register". in /var/www/task.local/vendor/yiisoft/yii2/base/Module.php:537
Stack trace:
#0 /var/www/task.local/vendor/yiisoft/yii2/web/Application.php(103): yii\base\Module->runAction('register', Array)
#1 /var/www/task.local/vendor/yiisoft" while reading upstream, client: 127.0.0.1, server: task.local.frontend, request: "GET /register HTTP/1.1", upstream: "fastcgi://unix:/var/run/php/php7.2-fpm.sock:", host: "task.local.frontend", referrer: "http://task.local.frontend/login?error=%D0%92%D1%8B+%D0%BD%D0%B5%D0%B0%D0%B2%D1%82%D0%BE%D1%80%D0%B8%D0%B7%D0%B8%D1%80%D0%BE%D0%B2%D0%B0%D0%BD%D1%8B"
2019/07/03 19:09:02 [error] 991#991: *136 FastCGI sent in stderr: "PHP message: An Error occurred while handling another error:
yii\base\InvalidRouteException: Unable to resolve the request: site/error in /var/www/task.local/vendor/yiisoft/yii2/base/Controller.php:128
Stack trace:
#0 /var/www/task.local/vendor/yiisoft/yii2/base/Module.php(528): yii\base\Controller->runAction('error', Array)
#1 /var/www/task.local/vendor/yiisoft/yii2/web/ErrorHandler.php(108): yii\base\Module->runAction('site/error')
#2 /var/www/task.local/vendor/yiisoft/yii2/base/ErrorHandler.php(111): yii\web\ErrorHandler->renderException(Object(yii\web\NotFoundHttpException))
#3 [internal function]: yii\base\ErrorHandler->handleException(Object(yii\web\NotFoundHttpException))
#4 {main}
Previous exception:
yii\base\InvalidRouteException: Unable to resolve the request: site/about in /var/www/task.local/vendor/yiisoft/yii2/base/Controller.php:128
Stack trace:
#0 /var/www/task.local/vendor/yiisoft/yii2/base/Module.php(528): yii\base\Controller->runAction('about', Array)
#1 /var/www/task.local/vendor/yiisof" while reading upstream, client: 127.0.0.1, server: task.local.frontend, request: "GET /site/about HTTP/1.1", upstream: "fastcgi://unix:/var/run/php/php7.2-fpm.sock:", host: "task.local.frontend", referrer: "http://task.local.frontend/login?error=%D0%92%D1%8B+%D0%BD%D0%B5%D0%B0%D0%B2%D1%82%D0%BE%D1%80%D0%B8%D0%B7%D0%B8%D1%80%D0%BE%D0%B2%D0%B0%D0%BD%D1%8B"
2019/07/03 19:18:30 [error] 991#991: *152 FastCGI sent in stderr: "PHP message: An Error occurred while handling another error:
yii\base\InvalidRouteException: Unable to resolve the request: site/error in /var/www/task.local/vendor/yiisoft/yii2/base/Controller.php:128
Stack trace:
#0 /var/www/task.local/vendor/yiisoft/yii2/base/Module.php(528): yii\base\Controller->runAction('error', Array)
#1 /var/www/task.local/vendor/yiisoft/yii2/web/ErrorHandler.php(108): yii\base\Module->runAction('site/error')
#2 /var/www/task.local/vendor/yiisoft/yii2/base/ErrorHandler.php(111): yii\web\ErrorHandler->renderException(Object(yii\web\NotFoundHttpException))
#3 [internal function]: yii\base\ErrorHandler->handleException(Object(yii\web\NotFoundHttpException))
#4 {main}
Previous exception:
yii\base\InvalidRouteException: Unable to resolve the request "auth". in /var/www/task.local/vendor/yiisoft/yii2/base/Module.php:537
Stack trace:
#0 /var/www/task.local/vendor/yiisoft/yii2/web/Application.php(103): yii\base\Module->runAction('auth', Array)
#1 /var/www/task.local/vendor/yiisoft/yii2/ba" while reading upstream, client: 127.0.0.1, server: task.local.frontend, request: "POST /auth HTTP/1.1", upstream: "fastcgi://unix:/var/run/php/php7.2-fpm.sock:", host: "task.local.frontend", referrer: "http://task.local.frontend/login?error=%D0%92%D1%8B+%D0%BD%D0%B5%D0%B0%D0%B2%D1%82%D0%BE%D1%80%D0%B8%D0%B7%D0%B8%D1%80%D0%BE%D0%B2%D0%B0%D0%BD%D1%8B"
2019/07/03 19:19:32 [error] 991#991: *152 FastCGI sent in stderr: "PHP message: An Error occurred while handling another error:
yii\base\InvalidRouteException: Unable to resolve the request: site/error in /var/www/task.local/vendor/yiisoft/yii2/base/Controller.php:128
Stack trace:
#0 /var/www/task.local/vendor/yiisoft/yii2/base/Module.php(528): yii\base\Controller->runAction('error', Array)
#1 /var/www/task.local/vendor/yiisoft/yii2/web/ErrorHandler.php(108): yii\base\Module->runAction('site/error')
#2 /var/www/task.local/vendor/yiisoft/yii2/base/ErrorHandler.php(111): yii\web\ErrorHandler->renderException(Object(yii\web\BadRequestHttpException))
#3 [internal function]: yii\base\ErrorHandler->handleException(Object(yii\web\BadRequestHttpException))
#4 {main}
Previous exception:
yii\web\BadRequestHttpException: Не удалось проверить переданные данные. in /var/www/task.local/vendor/yiisoft/yii2/web/Controller.php:166
Stack trace:
#0 /var/www/task.local/vendor/yiisoft/yii2/base/Controller.php(155): yii\web\Controller->beforeAction(Object(yii" while reading upstream, client: 127.0.0.1, server: task.local.frontend, request: "POST /auth HTTP/1.1", upstream: "fastcgi://unix:/var/run/php/php7.2-fpm.sock:", host: "task.local.frontend", referrer: "http://task.local.frontend/login?error=%D0%92%D1%8B+%D0%BD%D0%B5%D0%B0%D0%B2%D1%82%D0%BE%D1%80%D0%B8%D0%B7%D0%B8%D1%80%D0%BE%D0%B2%D0%B0%D0%BD%D1%8B"
2019/07/03 19:19:49 [error] 991#991: *152 FastCGI sent in stderr: "PHP message: An Error occurred while handling another error:
yii\base\InvalidRouteException: Unable to resolve the request: site/error in /var/www/task.local/vendor/yiisoft/yii2/base/Controller.php:128
Stack trace:
#0 /var/www/task.local/vendor/yiisoft/yii2/base/Module.php(528): yii\base\Controller->runAction('error', Array)
#1 /var/www/task.local/vendor/yiisoft/yii2/web/ErrorHandler.php(108): yii\base\Module->runAction('site/error')
#2 /var/www/task.local/vendor/yiisoft/yii2/base/ErrorHandler.php(111): yii\web\ErrorHandler->renderException(Object(yii\web\BadRequestHttpException))
#3 [internal function]: yii\base\ErrorHandler->handleException(Object(yii\web\BadRequestHttpException))
#4 {main}
Previous exception:
yii\web\BadRequestHttpException: Не удалось проверить переданные данные. in /var/www/task.local/vendor/yiisoft/yii2/web/Controller.php:166
Stack trace:
#0 /var/www/task.local/vendor/yiisoft/yii2/base/Controller.php(155): yii\web\Controller->beforeAction(Object(yii" while reading upstream, client: 127.0.0.1, server: task.local.frontend, request: "POST /auth HTTP/1.1", upstream: "fastcgi://unix:/var/run/php/php7.2-fpm.sock:", host: "task.local.frontend", referrer: "http://task.local.frontend/login?error=%D0%92%D1%8B+%D0%BD%D0%B5%D0%B0%D0%B2%D1%82%D0%BE%D1%80%D0%B8%D0%B7%D0%B8%D1%80%D0%BE%D0%B2%D0%B0%D0%BD%D1%8B"
2019/07/03 19:19:54 [error] 991#991: *152 FastCGI sent in stderr: "PHP message: An Error occurred while handling another error:
yii\base\InvalidRouteException: Unable to resolve the request: site/error in /var/www/task.local/vendor/yiisoft/yii2/base/Controller.php:128
Stack trace:
#0 /var/www/task.local/vendor/yiisoft/yii2/base/Module.php(528): yii\base\Controller->runAction('error', Array)
#1 /var/www/task.local/vendor/yiisoft/yii2/web/ErrorHandler.php(108): yii\base\Module->runAction('site/error')
#2 /var/www/task.local/vendor/yiisoft/yii2/base/ErrorHandler.php(111): yii\web\ErrorHandler->renderException(Object(yii\web\BadRequestHttpException))
#3 [internal function]: yii\base\ErrorHandler->handleException(Object(yii\web\BadRequestHttpException))
#4 {main}
Previous exception:
yii\web\BadRequestHttpException: Не удалось проверить переданные данные. in /var/www/task.local/vendor/yiisoft/yii2/web/Controller.php:166
Stack trace:
#0 /var/www/task.local/vendor/yiisoft/yii2/base/Controller.php(155): yii\web\Controller->beforeAction(Object(yii" while reading upstream, client: 127.0.0.1, server: task.local.frontend, request: "POST /auth HTTP/1.1", upstream: "fastcgi://unix:/var/run/php/php7.2-fpm.sock:", host: "task.local.frontend", referrer: "http://task.local.frontend/login?error=%D0%92%D1%8B+%D0%BD%D0%B5%D0%B0%D0%B2%D1%82%D0%BE%D1%80%D0%B8%D0%B7%D0%B8%D1%80%D0%BE%D0%B2%D0%B0%D0%BD%D1%8B"
2019/07/03 19:20:11 [error] 991#991: *152 FastCGI sent in stderr: "PHP message: An Error occurred while handling another error:
yii\base\InvalidRouteException: Unable to resolve the request: site/error in /var/www/task.local/vendor/yiisoft/yii2/base/Controller.php:128
Stack trace:
#0 /var/www/task.local/vendor/yiisoft/yii2/base/Module.php(528): yii\base\Controller->runAction('error', Array)
#1 /var/www/task.local/vendor/yiisoft/yii2/web/ErrorHandler.php(108): yii\base\Module->runAction('site/error')
#2 /var/www/task.local/vendor/yiisoft/yii2/base/ErrorHandler.php(111): yii\web\ErrorHandler->renderException(Object(yii\web\BadRequestHttpException))
#3 [internal function]: yii\base\ErrorHandler->handleException(Object(yii\web\BadRequestHttpException))
#4 {main}
Previous exception:
yii\web\BadRequestHttpException: Не удалось проверить переданные данные. in /var/www/task.local/vendor/yiisoft/yii2/web/Controller.php:166
Stack trace:
#0 /var/www/task.local/vendor/yiisoft/yii2/base/Controller.php(155): yii\web\Controller->beforeAction(Object(yii" while reading upstream, client: 127.0.0.1, server: task.local.frontend, request: "POST /auth HTTP/1.1", upstream: "fastcgi://unix:/var/run/php/php7.2-fpm.sock:", host: "task.local.frontend", referrer: "http://task.local.frontend/login?error=%D0%92%D1%8B+%D0%BD%D0%B5%D0%B0%D0%B2%D1%82%D0%BE%D1%80%D0%B8%D0%B7%D0%B8%D1%80%D0%BE%D0%B2%D0%B0%D0%BD%D1%8B"
2019/07/03 19:22:25 [error] 991#991: *164 FastCGI sent in stderr: "PHP message: An Error occurred while handling another error:
yii\base\InvalidRouteException: Unable to resolve the request: site/error in /var/www/task.local/vendor/yiisoft/yii2/base/Controller.php:128
Stack trace:
#0 /var/www/task.local/vendor/yiisoft/yii2/base/Module.php(528): yii\base\Controller->runAction('error', Array)
#1 /var/www/task.local/vendor/yiisoft/yii2/web/ErrorHandler.php(108): yii\base\Module->runAction('site/error')
#2 /var/www/task.local/vendor/yiisoft/yii2/base/ErrorHandler.php(111): yii\web\ErrorHandler->renderException(Object(yii\web\BadRequestHttpException))
#3 [internal function]: yii\base\ErrorHandler->handleException(Object(yii\web\BadRequestHttpException))
#4 {main}
Previous exception:
yii\web\BadRequestHttpException: Не удалось проверить переданные данные. in /var/www/task.local/vendor/yiisoft/yii2/web/Controller.php:166
Stack trace:
#0 /var/www/task.local/vendor/yiisoft/yii2/base/Controller.php(155): yii\web\Controller->beforeAction(Object(yii" while reading upstream, client: 127.0.0.1, server: task.local.frontend, request: "POST /auth HTTP/1.1", upstream: "fastcgi://unix:/var/run/php/php7.2-fpm.sock:", host: "task.local.frontend", referrer: "http://task.local.frontend/login?error=%D0%92%D1%8B+%D0%BD%D0%B5%D0%B0%D0%B2%D1%82%D0%BE%D1%80%D0%B8%D0%B7%D0%B8%D1%80%D0%BE%D0%B2%D0%B0%D0%BD%D1%8B"
2019/07/03 19:22:32 [error] 991#991: *164 FastCGI sent in stderr: "PHP message: An Error occurred while handling another error:
yii\base\InvalidRouteException: Unable to resolve the request: site/error in /var/www/task.local/vendor/yiisoft/yii2/base/Controller.php:128
Stack trace:
#0 /var/www/task.local/vendor/yiisoft/yii2/base/Module.php(528): yii\base\Controller->runAction('error', Array)
#1 /var/www/task.local/vendor/yiisoft/yii2/web/ErrorHandler.php(108): yii\base\Module->runAction('site/error')
#2 /var/www/task.local/vendor/yiisoft/yii2/base/ErrorHandler.php(111): yii\web\ErrorHandler->renderException(Object(yii\web\BadRequestHttpException))
#3 [internal function]: yii\base\ErrorHandler->handleException(Object(yii\web\BadRequestHttpException))
#4 {main}
Previous exception:
yii\web\BadRequestHttpException: Не удалось проверить переданные данные. in /var/www/task.local/vendor/yiisoft/yii2/web/Controller.php:166
Stack trace:
#0 /var/www/task.local/vendor/yiisoft/yii2/base/Controller.php(155): yii\web\Controller->beforeAction(Object(yii" while reading upstream, client: 127.0.0.1, server: task.local.frontend, request: "POST /auth HTTP/1.1", upstream: "fastcgi://unix:/var/run/php/php7.2-fpm.sock:", host: "task.local.frontend", referrer: "http://task.local.frontend/login?error=%D0%92%D1%8B+%D0%BD%D0%B5%D0%B0%D0%B2%D1%82%D0%BE%D1%80%D0%B8%D0%B7%D0%B8%D1%80%D0%BE%D0%B2%D0%B0%D0%BD%D1%8B"
2019/07/03 19:24:30 [error] 991#991: *172 FastCGI sent in stderr: "PHP message: An Error occurred while handling another error:
yii\base\InvalidRouteException: Unable to resolve the request: site/error in /var/www/task.local/vendor/yiisoft/yii2/base/Controller.php:128
Stack trace:
#0 /var/www/task.local/vendor/yiisoft/yii2/base/Module.php(528): yii\base\Controller->runAction('error', Array)
#1 /var/www/task.local/vendor/yiisoft/yii2/web/ErrorHandler.php(108): yii\base\Module->runAction('site/error')
#2 /var/www/task.local/vendor/yiisoft/yii2/base/ErrorHandler.php(111): yii\web\ErrorHandler->renderException(Object(yii\web\BadRequestHttpException))
#3 [internal function]: yii\base\ErrorHandler->handleException(Object(yii\web\BadRequestHttpException))
#4 {main}
Previous exception:
yii\web\BadRequestHttpException: Не удалось проверить переданные данные. in /var/www/task.local/vendor/yiisoft/yii2/web/Controller.php:166
Stack trace:
#0 /var/www/task.local/vendor/yiisoft/yii2/base/Controller.php(155): yii\web\Controller->beforeAction(Object(yii" while reading upstream, client: 127.0.0.1, server: task.local.frontend, request: "POST /auth HTTP/1.1", upstream: "fastcgi://unix:/var/run/php/php7.2-fpm.sock:", host: "task.local.frontend", referrer: "http://task.local.frontend/login?error=%D0%92%D1%8B+%D0%BD%D0%B5%D0%B0%D0%B2%D1%82%D0%BE%D1%80%D0%B8%D0%B7%D0%B8%D1%80%D0%BE%D0%B2%D0%B0%D0%BD%D1%8B"
2019/07/03 19:24:34 [error] 991#991: *172 FastCGI sent in stderr: "PHP message: An Error occurred while handling another error:
yii\base\InvalidRouteException: Unable to resolve the request: site/error in /var/www/task.local/vendor/yiisoft/yii2/base/Controller.php:128
Stack trace:
#0 /var/www/task.local/vendor/yiisoft/yii2/base/Module.php(528): yii\base\Controller->runAction('error', Array)
#1 /var/www/task.local/vendor/yiisoft/yii2/web/ErrorHandler.php(108): yii\base\Module->runAction('site/error')
#2 /var/www/task.local/vendor/yiisoft/yii2/base/ErrorHandler.php(111): yii\web\ErrorHandler->renderException(Object(yii\web\NotFoundHttpException))
#3 [internal function]: yii\base\ErrorHandler->handleException(Object(yii\web\NotFoundHttpException))
#4 {main}
Previous exception:
yii\base\InvalidRouteException: Unable to resolve the request "auth/". in /var/www/task.local/vendor/yiisoft/yii2/base/Module.php:537
Stack trace:
#0 /var/www/task.local/vendor/yiisoft/yii2/web/Application.php(103): yii\base\Module->runAction('auth/', Array)
#1 /var/www/task.local/vendor/yiisoft/yii2/" while reading upstream, client: 127.0.0.1, server: task.local.frontend, request: "POST /auth/ HTTP/1.1", upstream: "fastcgi://unix:/var/run/php/php7.2-fpm.sock:", host: "task.local.frontend", referrer: "http://task.local.frontend/login?error=%D0%92%D1%8B+%D0%BD%D0%B5%D0%B0%D0%B2%D1%82%D0%BE%D1%80%D0%B8%D0%B7%D0%B8%D1%80%D0%BE%D0%B2%D0%B0%D0%BD%D1%8B"
2019/07/03 19:25:00 [error] 991#991: *172 FastCGI sent in stderr: "PHP message: An Error occurred while handling another error:
yii\base\InvalidRouteException: Unable to resolve the request: site/error in /var/www/task.local/vendor/yiisoft/yii2/base/Controller.php:128
Stack trace:
#0 /var/www/task.local/vendor/yiisoft/yii2/base/Module.php(528): yii\base\Controller->runAction('error', Array)
#1 /var/www/task.local/vendor/yiisoft/yii2/web/ErrorHandler.php(108): yii\base\Module->runAction('site/error')
#2 /var/www/task.local/vendor/yiisoft/yii2/base/ErrorHandler.php(111): yii\web\ErrorHandler->renderException(Object(yii\web\BadRequestHttpException))
#3 [internal function]: yii\base\ErrorHandler->handleException(Object(yii\web\BadRequestHttpException))
#4 {main}
Previous exception:
yii\web\BadRequestHttpException: Не удалось проверить переданные данные. in /var/www/task.local/vendor/yiisoft/yii2/web/Controller.php:166
Stack trace:
#0 /var/www/task.local/vendor/yiisoft/yii2/base/Controller.php(155): yii\web\Controller->beforeAction(Object(yii" while reading upstream, client: 127.0.0.1, server: task.local.frontend, request: "POST /user HTTP/1.1", upstream: "fastcgi://unix:/var/run/php/php7.2-fpm.sock:", host: "task.local.frontend", referrer: "http://task.local.frontend/login?error=%D0%92%D1%8B+%D0%BD%D0%B5%D0%B0%D0%B2%D1%82%D0%BE%D1%80%D0%B8%D0%B7%D0%B8%D1%80%D0%BE%D0%B2%D0%B0%D0%BD%D1%8B"
2019/07/03 19:25:28 [error] 991#991: *172 FastCGI sent in stderr: "PHP message: An Error occurred while handling another error:
yii\base\InvalidRouteException: Unable to resolve the request: site/error in /var/www/task.local/vendor/yiisoft/yii2/base/Controller.php:128
Stack trace:
#0 /var/www/task.local/vendor/yiisoft/yii2/base/Module.php(528): yii\base\Controller->runAction('error', Array)
#1 /var/www/task.local/vendor/yiisoft/yii2/web/ErrorHandler.php(108): yii\base\Module->runAction('site/error')
#2 /var/www/task.local/vendor/yiisoft/yii2/base/ErrorHandler.php(111): yii\web\ErrorHandler->renderException(Object(yii\web\BadRequestHttpException))
#3 [internal function]: yii\base\ErrorHandler->handleException(Object(yii\web\BadRequestHttpException))
#4 {main}
Previous exception:
yii\web\BadRequestHttpException: Не удалось проверить переданные данные. in /var/www/task.local/vendor/yiisoft/yii2/web/Controller.php:166
Stack trace:
#0 /var/www/task.local/vendor/yiisoft/yii2/base/Controller.php(155): yii\web\Controller->beforeAction(Object(yii" while reading upstream, client: 127.0.0.1, server: task.local.frontend, request: "POST /user/index HTTP/1.1", upstream: "fastcgi://unix:/var/run/php/php7.2-fpm.sock:", host: "task.local.frontend", referrer: "http://task.local.frontend/login?error=%D0%92%D1%8B+%D0%BD%D0%B5%D0%B0%D0%B2%D1%82%D0%BE%D1%80%D0%B8%D0%B7%D0%B8%D1%80%D0%BE%D0%B2%D0%B0%D0%BD%D1%8B"
2019/07/03 19:29:58 [error] 991#991: *186 FastCGI sent in stderr: "PHP message: An Error occurred while handling another error:
yii\base\InvalidRouteException: Unable to resolve the request: site/error in /var/www/task.local/vendor/yiisoft/yii2/base/Controller.php:128
Stack trace:
#0 /var/www/task.local/vendor/yiisoft/yii2/base/Module.php(528): yii\base\Controller->runAction('error', Array)
#1 /var/www/task.local/vendor/yiisoft/yii2/web/ErrorHandler.php(108): yii\base\Module->runAction('site/error')
#2 /var/www/task.local/vendor/yiisoft/yii2/base/ErrorHandler.php(111): yii\web\ErrorHandler->renderException(Object(yii\web\BadRequestHttpException))
#3 [internal function]: yii\base\ErrorHandler->handleException(Object(yii\web\BadRequestHttpException))
#4 {main}
Previous exception:
yii\web\BadRequestHttpException: Не удалось проверить переданные данные. in /var/www/task.local/vendor/yiisoft/yii2/web/Controller.php:166
Stack trace:
#0 /var/www/task.local/vendor/yiisoft/yii2/base/Controller.php(155): yii\web\Controller->beforeAction(Object(yii" while reading upstream, client: 127.0.0.1, server: task.local.frontend, request: "POST /user/index HTTP/1.1", upstream: "fastcgi://unix:/var/run/php/php7.2-fpm.sock:", host: "task.local.frontend", referrer: "http://task.local.frontend/login?error=%D0%92%D1%8B+%D0%BD%D0%B5%D0%B0%D0%B2%D1%82%D0%BE%D1%80%D0%B8%D0%B7%D0%B8%D1%80%D0%BE%D0%B2%D0%B0%D0%BD%D1%8B"
2019/07/03 19:30:13 [error] 991#991: *186 FastCGI sent in stderr: "PHP message: An Error occurred while handling another error:
yii\base\InvalidRouteException: Unable to resolve the request: site/error in /var/www/task.local/vendor/yiisoft/yii2/base/Controller.php:128
Stack trace:
#0 /var/www/task.local/vendor/yiisoft/yii2/base/Module.php(528): yii\base\Controller->runAction('error', Array)
#1 /var/www/task.local/vendor/yiisoft/yii2/web/ErrorHandler.php(108): yii\base\Module->runAction('site/error')
#2 /var/www/task.local/vendor/yiisoft/yii2/base/ErrorHandler.php(111): yii\web\ErrorHandler->renderException(Object(yii\web\BadRequestHttpException))
#3 [internal function]: yii\base\ErrorHandler->handleException(Object(yii\web\BadRequestHttpException))
#4 {main}
Previous exception:
yii\web\BadRequestHttpException: Не удалось проверить переданные данные. in /var/www/task.local/vendor/yiisoft/yii2/web/Controller.php:166
Stack trace:
#0 /var/www/task.local/vendor/yiisoft/yii2/base/Controller.php(155): yii\web\Controller->beforeAction(Object(yii" while reading upstream, client: 127.0.0.1, server: task.local.frontend, request: "POST /user/index HTTP/1.1", upstream: "fastcgi://unix:/var/run/php/php7.2-fpm.sock:", host: "task.local.frontend", referrer: "http://task.local.frontend/login?error=%D0%92%D1%8B+%D0%BD%D0%B5%D0%B0%D0%B2%D1%82%D0%BE%D1%80%D0%B8%D0%B7%D0%B8%D1%80%D0%BE%D0%B2%D0%B0%D0%BD%D1%8B"
2019/07/03 19:30:54 [error] 991#991: *186 FastCGI sent in stderr: "PHP message: An Error occurred while handling another error:
yii\base\InvalidRouteException: Unable to resolve the request: site/error in /var/www/task.local/vendor/yiisoft/yii2/base/Controller.php:128
Stack trace:
#0 /var/www/task.local/vendor/yiisoft/yii2/base/Module.php(528): yii\base\Controller->runAction('error', Array)
#1 /var/www/task.local/vendor/yiisoft/yii2/web/ErrorHandler.php(108): yii\base\Module->runAction('site/error')
#2 /var/www/task.local/vendor/yiisoft/yii2/base/ErrorHandler.php(111): yii\web\ErrorHandler->renderException(Object(yii\web\BadRequestHttpException))
#3 [internal function]: yii\base\ErrorHandler->handleException(Object(yii\web\BadRequestHttpException))
#4 {main}
Previous exception:
yii\web\BadRequestHttpException: Не удалось проверить переданные данные. in /var/www/task.local/vendor/yiisoft/yii2/web/Controller.php:166
Stack trace:
#0 /var/www/task.local/vendor/yiisoft/yii2/base/Controller.php(155): yii\web\Controller->beforeAction(Object(yii" while reading upstream, client: 127.0.0.1, server: task.local.frontend, request: "POST /user/index HTTP/1.1", upstream: "fastcgi://unix:/var/run/php/php7.2-fpm.sock:", host: "task.local.frontend", referrer: "http://task.local.frontend/login?error=%D0%92%D1%8B+%D0%BD%D0%B5%D0%B0%D0%B2%D1%82%D0%BE%D1%80%D0%B8%D0%B7%D0%B8%D1%80%D0%BE%D0%B2%D0%B0%D0%BD%D1%8B"
2019/07/03 19:32:35 [error] 991#991: *192 FastCGI sent in stderr: "PHP message: An Error occurred while handling another error:
yii\base\InvalidRouteException: Unable to resolve the request: site/error in /var/www/task.local/vendor/yiisoft/yii2/base/Controller.php:128
Stack trace:
#0 /var/www/task.local/vendor/yiisoft/yii2/base/Module.php(528): yii\base\Controller->runAction('error', Array)
#1 /var/www/task.local/vendor/yiisoft/yii2/web/ErrorHandler.php(108): yii\base\Module->runAction('site/error')
#2 /var/www/task.local/vendor/yiisoft/yii2/base/ErrorHandler.php(111): yii\web\ErrorHandler->renderException(Object(yii\web\BadRequestHttpException))
#3 [internal function]: yii\base\ErrorHandler->handleException(Object(yii\web\BadRequestHttpException))
#4 {main}
Previous exception:
yii\web\BadRequestHttpException: Не удалось проверить переданные данные. in /var/www/task.local/vendor/yiisoft/yii2/web/Controller.php:166
Stack trace:
#0 /var/www/task.local/vendor/yiisoft/yii2/base/Controller.php(155): yii\web\Controller->beforeAction(Object(yii" while reading upstream, client: 127.0.0.1, server: task.local.frontend, request: "POST /user/index HTTP/1.1", upstream: "fastcgi://unix:/var/run/php/php7.2-fpm.sock:", host: "task.local.frontend", referrer: "http://task.local.frontend/login?error=%D0%92%D1%8B+%D0%BD%D0%B5%D0%B0%D0%B2%D1%82%D0%BE%D1%80%D0%B8%D0%B7%D0%B8%D1%80%D0%BE%D0%B2%D0%B0%D0%BD%D1%8B"
2019/07/03 19:32:39 [error] 991#991: *192 FastCGI sent in stderr: "PHP message: An Error occurred while handling another error:
yii\base\InvalidRouteException: Unable to resolve the request: site/error in /var/www/task.local/vendor/yiisoft/yii2/base/Controller.php:128
Stack trace:
#0 /var/www/task.local/vendor/yiisoft/yii2/base/Module.php(528): yii\base\Controller->runAction('error', Array)
#1 /var/www/task.local/vendor/yiisoft/yii2/web/ErrorHandler.php(108): yii\base\Module->runAction('site/error')
#2 /var/www/task.local/vendor/yiisoft/yii2/base/ErrorHandler.php(111): yii\web\ErrorHandler->renderException(Object(yii\web\BadRequestHttpException))
#3 [internal function]: yii\base\ErrorHandler->handleException(Object(yii\web\BadRequestHttpException))
#4 {main}
Previous exception:
yii\web\BadRequestHttpException: Не удалось проверить переданные данные. in /var/www/task.local/vendor/yiisoft/yii2/web/Controller.php:166
Stack trace:
#0 /var/www/task.local/vendor/yiisoft/yii2/base/Controller.php(155): yii\web\Controller->beforeAction(Object(yii" while reading upstream, client: 127.0.0.1, server: task.local.frontend, request: "POST /auth HTTP/1.1", upstream: "fastcgi://unix:/var/run/php/php7.2-fpm.sock:", host: "task.local.frontend", referrer: "http://task.local.frontend/login?error=%D0%92%D1%8B+%D0%BD%D0%B5%D0%B0%D0%B2%D1%82%D0%BE%D1%80%D0%B8%D0%B7%D0%B8%D1%80%D0%BE%D0%B2%D0%B0%D0%BD%D1%8B"
2019/07/03 19:37:14 [error] 991#991: *199 FastCGI sent in stderr: "PHP message: An Error occurred while handling another error:
yii\base\InvalidRouteException: Unable to resolve the request: site/error in /var/www/task.local/vendor/yiisoft/yii2/base/Controller.php:128
Stack trace:
#0 /var/www/task.local/vendor/yiisoft/yii2/base/Module.php(528): yii\base\Controller->runAction('error', Array)
#1 /var/www/task.local/vendor/yiisoft/yii2/web/ErrorHandler.php(108): yii\base\Module->runAction('site/error')
#2 /var/www/task.local/vendor/yiisoft/yii2/base/ErrorHandler.php(111): yii\web\ErrorHandler->renderException(Object(yii\web\BadRequestHttpException))
#3 [internal function]: yii\base\ErrorHandler->handleException(Object(yii\web\BadRequestHttpException))
#4 {main}
Previous exception:
yii\web\BadRequestHttpException: Не удалось проверить переданные данные. in /var/www/task.local/vendor/yiisoft/yii2/web/Controller.php:166
Stack trace:
#0 /var/www/task.local/vendor/yiisoft/yii2/base/Controller.php(155): yii\web\Controller->beforeAction(Object(yii" while reading upstream, client: 127.0.0.1, server: task.local.frontend, request: "POST /auth HTTP/1.1", upstream: "fastcgi://unix:/var/run/php/php7.2-fpm.sock:", host: "task.local.frontend", referrer: "http://task.local.frontend/login?error=%D0%92%D1%8B+%D0%BD%D0%B5%D0%B0%D0%B2%D1%82%D0%BE%D1%80%D0%B8%D0%B7%D0%B8%D1%80%D0%BE%D0%B2%D0%B0%D0%BD%D1%8B"
2019/07/03 19:38:04 [error] 991#991: *199 FastCGI sent in stderr: "PHP message: An Error occurred while handling another error:
yii\base\InvalidRouteException: Unable to resolve the request: site/error in /var/www/task.local/vendor/yiisoft/yii2/base/Controller.php:128
Stack trace:
#0 /var/www/task.local/vendor/yiisoft/yii2/base/Module.php(528): yii\base\Controller->runAction('error', Array)
#1 /var/www/task.local/vendor/yiisoft/yii2/web/ErrorHandler.php(108): yii\base\Module->runAction('site/error')
#2 /var/www/task.local/vendor/yiisoft/yii2/base/ErrorHandler.php(111): yii\web\ErrorHandler->renderException(Object(yii\web\BadRequestHttpException))
#3 [internal function]: yii\base\ErrorHandler->handleException(Object(yii\web\BadRequestHttpException))
#4 {main}
Previous exception:
yii\web\BadRequestHttpException: Не удалось проверить переданные данные. in /var/www/task.local/vendor/yiisoft/yii2/web/Controller.php:166
Stack trace:
#0 /var/www/task.local/vendor/yiisoft/yii2/base/Controller.php(155): yii\web\Controller->beforeAction(Object(yii" while reading upstream, client: 127.0.0.1, server: task.local.frontend, request: "POST /auth HTTP/1.1", upstream: "fastcgi://unix:/var/run/php/php7.2-fpm.sock:", host: "task.local.frontend", referrer: "http://task.local.frontend/login?error=%D0%92%D1%8B+%D0%BD%D0%B5%D0%B0%D0%B2%D1%82%D0%BE%D1%80%D0%B8%D0%B7%D0%B8%D1%80%D0%BE%D0%B2%D0%B0%D0%BD%D1%8B"
2019/07/03 19:40:29 [error] 991#991: *208 FastCGI sent in stderr: "PHP message: An Error occurred while handling another error:
yii\base\InvalidRouteException: Unable to resolve the request: site/error in /var/www/task.local/vendor/yiisoft/yii2/base/Controller.php:128
Stack trace:
#0 /var/www/task.local/vendor/yiisoft/yii2/base/Module.php(528): yii\base\Controller->runAction('error', Array)
#1 /var/www/task.local/vendor/yiisoft/yii2/web/ErrorHandler.php(108): yii\base\Module->runAction('site/error')
#2 /var/www/task.local/vendor/yiisoft/yii2/base/ErrorHandler.php(111): yii\web\ErrorHandler->renderException(Object(yii\web\BadRequestHttpException))
#3 [internal function]: yii\base\ErrorHandler->handleException(Object(yii\web\BadRequestHttpException))
#4 {main}
Previous exception:
yii\web\BadRequestHttpException: Не удалось проверить переданные данные. in /var/www/task.local/vendor/yiisoft/yii2/web/Controller.php:166
Stack trace:
#0 /var/www/task.local/vendor/yiisoft/yii2/base/Controller.php(155): yii\web\Controller->beforeAction(Object(yii" while reading upstream, client: 127.0.0.1, server: task.local.frontend, request: "POST /auth HTTP/1.1", upstream: "fastcgi://unix:/var/run/php/php7.2-fpm.sock:", host: "task.local.frontend", referrer: "http://task.local.frontend/login?error=%D0%92%D1%8B+%D0%BD%D0%B5%D0%B0%D0%B2%D1%82%D0%BE%D1%80%D0%B8%D0%B7%D0%B8%D1%80%D0%BE%D0%B2%D0%B0%D0%BD%D1%8B"
2019/07/03 19:44:45 [error] 991#991: *213 FastCGI sent in stderr: "PHP message: An Error occurred while handling another error:
yii\base\InvalidRouteException: Unable to resolve the request: site/error in /var/www/task.local/vendor/yiisoft/yii2/base/Controller.php:128
Stack trace:
#0 /var/www/task.local/vendor/yiisoft/yii2/base/Module.php(528): yii\base\Controller->runAction('error', Array)
#1 /var/www/task.local/vendor/yiisoft/yii2/web/ErrorHandler.php(108): yii\base\Module->runAction('site/error')
#2 /var/www/task.local/vendor/yiisoft/yii2/base/ErrorHandler.php(111): yii\web\ErrorHandler->renderException(Object(yii\web\BadRequestHttpException))
#3 [internal function]: yii\base\ErrorHandler->handleException(Object(yii\web\BadRequestHttpException))
#4 {main}
Previous exception:
yii\web\BadRequestHttpException: Не удалось проверить переданные данные. in /var/www/task.local/vendor/yiisoft/yii2/web/Controller.php:166
Stack trace:
#0 /var/www/task.local/vendor/yiisoft/yii2/base/Controller.php(155): yii\web\Controller->beforeAction(Object(yii" while reading upstream, client: 127.0.0.1, server: task.local.frontend, request: "POST /auth HTTP/1.1", upstream: "fastcgi://unix:/var/run/php/php7.2-fpm.sock:", host: "task.local.frontend", referrer: "http://task.local.frontend/login?error=%D0%92%D1%8B+%D0%BD%D0%B5%D0%B0%D0%B2%D1%82%D0%BE%D1%80%D0%B8%D0%B7%D0%B8%D1%80%D0%BE%D0%B2%D0%B0%D0%BD%D1%8B"
2019/07/03 19:45:02 [error] 991#991: *213 FastCGI sent in stderr: "PHP message: An Error occurred while handling another error:
yii\base\InvalidRouteException: Unable to resolve the request: site/error in /var/www/task.local/vendor/yiisoft/yii2/base/Controller.php:128
Stack trace:
#0 /var/www/task.local/vendor/yiisoft/yii2/base/Module.php(528): yii\base\Controller->runAction('error', Array)
#1 /var/www/task.local/vendor/yiisoft/yii2/web/ErrorHandler.php(108): yii\base\Module->runAction('site/error')
#2 /var/www/task.local/vendor/yiisoft/yii2/base/ErrorHandler.php(111): yii\web\ErrorHandler->renderException(Object(yii\web\BadRequestHttpException))
#3 [internal function]: yii\base\ErrorHandler->handleException(Object(yii\web\BadRequestHttpException))
#4 {main}
Previous exception:
yii\web\BadRequestHttpException: Не удалось проверить переданные данные. in /var/www/task.local/vendor/yiisoft/yii2/web/Controller.php:166
Stack trace:
#0 /var/www/task.local/vendor/yiisoft/yii2/base/Controller.php(155): yii\web\Controller->beforeAction(Object(yii" while reading upstream, client: 127.0.0.1, server: task.local.frontend, request: "POST /auth HTTP/1.1", upstream: "fastcgi://unix:/var/run/php/php7.2-fpm.sock:", host: "task.local.frontend", referrer: "http://task.local.frontend/login?error=%D0%92%D1%8B+%D0%BD%D0%B5%D0%B0%D0%B2%D1%82%D0%BE%D1%80%D0%B8%D0%B7%D0%B8%D1%80%D0%BE%D0%B2%D0%B0%D0%BD%D1%8B"
2019/07/03 19:50:19 [error] 991#991: *218 FastCGI sent in stderr: "PHP message: An Error occurred while handling another error:
yii\base\InvalidRouteException: Unable to resolve the request: site/error in /var/www/task.local/vendor/yiisoft/yii2/base/Controller.php:128
Stack trace:
#0 /var/www/task.local/vendor/yiisoft/yii2/base/Module.php(528): yii\base\Controller->runAction('error', Array)
#1 /var/www/task.local/vendor/yiisoft/yii2/web/ErrorHandler.php(108): yii\base\Module->runAction('site/error')
#2 /var/www/task.local/vendor/yiisoft/yii2/base/ErrorHandler.php(111): yii\web\ErrorHandler->renderException(Object(yii\web\BadRequestHttpException))
#3 [internal function]: yii\base\ErrorHandler->handleException(Object(yii\web\BadRequestHttpException))
#4 {main}
Previous exception:
yii\web\BadRequestHttpException: Не удалось проверить переданные данные. in /var/www/task.local/vendor/yiisoft/yii2/web/Controller.php:166
Stack trace:
#0 /var/www/task.local/vendor/yiisoft/yii2/base/Controller.php(155): yii\web\Controller->beforeAction(Object(yii" while reading upstream, client: 127.0.0.1, server: task.local.frontend, request: "POST /auth HTTP/1.1", upstream: "fastcgi://unix:/var/run/php/php7.2-fpm.sock:", host: "task.local.frontend", referrer: "http://task.local.frontend/login?error=%D0%92%D1%8B+%D0%BD%D0%B5%D0%B0%D0%B2%D1%82%D0%BE%D1%80%D0%B8%D0%B7%D0%B8%D1%80%D0%BE%D0%B2%D0%B0%D0%BD%D1%8B"
2019/07/03 19:51:21 [error] 991#991: *218 FastCGI sent in stderr: "PHP message: An Error occurred while handling another error:
yii\base\InvalidRouteException: Unable to resolve the request: site/error in /var/www/task.local/vendor/yiisoft/yii2/base/Controller.php:128
Stack trace:
#0 /var/www/task.local/vendor/yiisoft/yii2/base/Module.php(528): yii\base\Controller->runAction('error', Array)
#1 /var/www/task.local/vendor/yiisoft/yii2/web/ErrorHandler.php(108): yii\base\Module->runAction('site/error')
#2 /var/www/task.local/vendor/yiisoft/yii2/base/ErrorHandler.php(111): yii\web\ErrorHandler->renderException(Object(yii\web\BadRequestHttpException))
#3 [internal function]: yii\base\ErrorHandler->handleException(Object(yii\web\BadRequestHttpException))
#4 {main}
Previous exception:
yii\web\BadRequestHttpException: Не удалось проверить переданные данные. in /var/www/task.local/vendor/yiisoft/yii2/web/Controller.php:166
Stack trace:
#0 /var/www/task.local/vendor/yiisoft/yii2/base/Controller.php(155): yii\web\Controller->beforeAction(Object(yii" while reading upstream, client: 127.0.0.1, server: task.local.frontend, request: "POST /auth HTTP/1.1", upstream: "fastcgi://unix:/var/run/php/php7.2-fpm.sock:", host: "task.local.frontend", referrer: "http://task.local.frontend/login?error=%D0%92%D1%8B+%D0%BD%D0%B5%D0%B0%D0%B2%D1%82%D0%BE%D1%80%D0%B8%D0%B7%D0%B8%D1%80%D0%BE%D0%B2%D0%B0%D0%BD%D1%8B"
2019/07/03 20:05:04 [error] 991#991: *233 FastCGI sent in stderr: "PHP message: An Error occurred while handling another error:
yii\base\InvalidRouteException: Unable to resolve the request: site/error in /var/www/task.local/vendor/yiisoft/yii2/base/Controller.php:128
Stack trace:
#0 /var/www/task.local/vendor/yiisoft/yii2/base/Module.php(528): yii\base\Controller->runAction('error', Array)
#1 /var/www/task.local/vendor/yiisoft/yii2/web/ErrorHandler.php(108): yii\base\Module->runAction('site/error')
#2 /var/www/task.local/vendor/yiisoft/yii2/base/ErrorHandler.php(111): yii\web\ErrorHandler->renderException(Object(yii\web\BadRequestHttpException))
#3 [internal function]: yii\base\ErrorHandler->handleException(Object(yii\web\BadRequestHttpException))
#4 {main}
Previous exception:
yii\web\BadRequestHttpException: Не удалось проверить переданные данные. in /var/www/task.local/vendor/yiisoft/yii2/web/Controller.php:166
Stack trace:
#0 /var/www/task.local/vendor/yiisoft/yii2/base/Controller.php(155): yii\web\Controller->beforeAction(Object(yii" while reading upstream, client: 127.0.0.1, server: task.local.frontend, request: "POST /auth HTTP/1.1", upstream: "fastcgi://unix:/var/run/php/php7.2-fpm.sock:", host: "task.local.frontend", referrer: "http://task.local.frontend/login?error=%D0%92%D1%8B+%D0%BD%D0%B5%D0%B0%D0%B2%D1%82%D0%BE%D1%80%D0%B8%D0%B7%D0%B8%D1%80%D0%BE%D0%B2%D0%B0%D0%BD%D1%8B"
2019/07/03 20:05:11 [error] 991#991: *233 FastCGI sent in stderr: "PHP message: An Error occurred while handling another error:
yii\base\InvalidRouteException: Unable to resolve the request: site/error in /var/www/task.local/vendor/yiisoft/yii2/base/Controller.php:128
Stack trace:
#0 /var/www/task.local/vendor/yiisoft/yii2/base/Module.php(528): yii\base\Controller->runAction('error', Array)
#1 /var/www/task.local/vendor/yiisoft/yii2/web/ErrorHandler.php(108): yii\base\Module->runAction('site/error')
#2 /var/www/task.local/vendor/yiisoft/yii2/base/ErrorHandler.php(111): yii\web\ErrorHandler->renderException(Object(yii\web\BadRequestHttpException))
#3 [internal function]: yii\base\ErrorHandler->handleException(Object(yii\web\BadRequestHttpException))
#4 {main}
Previous exception:
yii\web\BadRequestHttpException: Не удалось проверить переданные данные. in /var/www/task.local/vendor/yiisoft/yii2/web/Controller.php:166
Stack trace:
#0 /var/www/task.local/vendor/yiisoft/yii2/base/Controller.php(155): yii\web\Controller->beforeAction(Object(yii" while reading upstream, client: 127.0.0.1, server: task.local.frontend, request: "POST /auth HTTP/1.1", upstream: "fastcgi://unix:/var/run/php/php7.2-fpm.sock:", host: "task.local.frontend", referrer: "http://task.local.frontend/login?error=%D0%92%D1%8B+%D0%BD%D0%B5%D0%B0%D0%B2%D1%82%D0%BE%D1%80%D0%B8%D0%B7%D0%B8%D1%80%D0%BE%D0%B2%D0%B0%D0%BD%D1%8B"
2019/07/03 20:05:21 [error] 991#991: *233 FastCGI sent in stderr: "PHP message: An Error occurred while handling another error:
yii\base\InvalidRouteException: Unable to resolve the request: site/error in /var/www/task.local/vendor/yiisoft/yii2/base/Controller.php:128
Stack trace:
#0 /var/www/task.local/vendor/yiisoft/yii2/base/Module.php(528): yii\base\Controller->runAction('error', Array)
#1 /var/www/task.local/vendor/yiisoft/yii2/web/ErrorHandler.php(108): yii\base\Module->runAction('site/error')
#2 /var/www/task.local/vendor/yiisoft/yii2/base/ErrorHandler.php(111): yii\web\ErrorHandler->renderException(Object(yii\web\BadRequestHttpException))
#3 [internal function]: yii\base\ErrorHandler->handleException(Object(yii\web\BadRequestHttpException))
#4 {main}
Previous exception:
yii\web\BadRequestHttpException: Не удалось проверить переданные данные. in /var/www/task.local/vendor/yiisoft/yii2/web/Controller.php:166
Stack trace:
#0 /var/www/task.local/vendor/yiisoft/yii2/base/Controller.php(155): yii\web\Controller->beforeAction(Object(yii" while reading upstream, client: 127.0.0.1, server: task.local.frontend, request: "POST /auth HTTP/1.1", upstream: "fastcgi://unix:/var/run/php/php7.2-fpm.sock:", host: "task.local.frontend", referrer: "http://task.local.frontend/login?error=%D0%92%D1%8B+%D0%BD%D0%B5%D0%B0%D0%B2%D1%82%D0%BE%D1%80%D0%B8%D0%B7%D0%B8%D1%80%D0%BE%D0%B2%D0%B0%D0%BD%D1%8B"
2019/07/03 20:05:55 [error] 991#991: *233 FastCGI sent in stderr: "PHP message: An Error occurred while handling another error:
yii\base\InvalidRouteException: Unable to resolve the request: site/error in /var/www/task.local/vendor/yiisoft/yii2/base/Controller.php:128
Stack trace:
#0 /var/www/task.local/vendor/yiisoft/yii2/base/Module.php(528): yii\base\Controller->runAction('error', Array)
#1 /var/www/task.local/vendor/yiisoft/yii2/web/ErrorHandler.php(108): yii\base\Module->runAction('site/error')
#2 /var/www/task.local/vendor/yiisoft/yii2/base/ErrorHandler.php(111): yii\web\ErrorHandler->renderException(Object(yii\web\BadRequestHttpException))
#3 [internal function]: yii\base\ErrorHandler->handleException(Object(yii\web\BadRequestHttpException))
#4 {main}
Previous exception:
yii\web\BadRequestHttpException: Не удалось проверить переданные данные. in /var/www/task.local/vendor/yiisoft/yii2/web/Controller.php:166
Stack trace:
#0 /var/www/task.local/vendor/yiisoft/yii2/base/Controller.php(155): yii\web\Controller->beforeAction(Object(yii" while reading upstream, client: 127.0.0.1, server: task.local.frontend, request: "POST /auth HTTP/1.1", upstream: "fastcgi://unix:/var/run/php/php7.2-fpm.sock:", host: "task.local.frontend", referrer: "http://task.local.frontend/login?error=%D0%92%D1%8B+%D0%BD%D0%B5%D0%B0%D0%B2%D1%82%D0%BE%D1%80%D0%B8%D0%B7%D0%B8%D1%80%D0%BE%D0%B2%D0%B0%D0%BD%D1%8B"
2019/07/04 16:22:03 [error] 961#961: *97 FastCGI sent in stderr: "PHP message: An Error occurred while handling another error:
yii\base\InvalidRouteException: Unable to resolve the request: site/error in /var/www/task.local/vendor/yiisoft/yii2/base/Controller.php:128
Stack trace:
#0 /var/www/task.local/vendor/yiisoft/yii2/base/Module.php(528): yii\base\Controller->runAction('error', Array)
#1 /var/www/task.local/vendor/yiisoft/yii2/web/ErrorHandler.php(108): yii\base\Module->runAction('site/error')
#2 /var/www/task.local/vendor/yiisoft/yii2/base/ErrorHandler.php(111): yii\web\ErrorHandler->renderException(Object(yii\web\NotFoundHttpException))
#3 [internal function]: yii\base\ErrorHandler->handleException(Object(yii\web\NotFoundHttpException))
#4 {main}
Previous exception:
yii\base\InvalidRouteException: Unable to resolve the request "l". in /var/www/task.local/vendor/yiisoft/yii2/base/Module.php:537
Stack trace:
#0 /var/www/task.local/vendor/yiisoft/yii2/web/Application.php(103): yii\base\Module->runAction('l', Array)
#1 /var/www/task.local/vendor/yiisoft/yii2/base/App" while reading upstream, client: 127.0.0.1, server: task.local.frontend, request: "GET /l HTTP/1.1", upstream: "fastcgi://unix:/var/run/php/php7.2-fpm.sock:", host: "task.local.frontend"
2019/07/04 16:24:51 [error] 961#961: *106 FastCGI sent in stderr: "PHP message: PHP Warning:  Uncaught yii\base\ErrorException: require_once(./views/homePage/index.php): failed to open stream: No such file or directory in /var/www/task.local/frontend/controllers/SiteController.php:23
Stack trace:
#0 /var/www/task.local/frontend/controllers/SiteController.php(23): yii\base\ErrorHandler->handleError(2, 'require_once(./...', '/var/www/task.l...', 23, Array)
#1 /var/www/task.local/frontend/controllers/SiteController.php(23): require_once()
#2 [internal function]: frontend\controllers\SiteController->actionIndex(false)
#3 /var/www/task.local/vendor/yiisoft/yii2/base/InlineAction.php(57): call_user_func_array(Array, Array)
#4 /var/www/task.local/vendor/yiisoft/yii2/base/Controller.php(157): yii\base\InlineAction->runWithParams(Array)
#5 /var/www/task.local/vendor/yiisoft/yii2/base/Module.php(528): yii\base\Controller->runAction('index', Array)
#6 /var/www/task.local/vendor/yiisoft/yii2/web/Application.php(103): yii\base\Module->runAction('site/index', Array)
#7 /var/www/task.l...
PHP message: PHP Fatal error:  frontend\controllers\SiteController::actionIndex(): Failed opening required './views/homePage/index.php' (include_path='.:/usr/share/php') in /var/www/task.local/frontend/controllers/SiteController.php on line 23" while reading response header from upstream, client: 127.0.0.1, server: task.local.frontend, request: "GET / HTTP/1.1", upstream: "fastcgi://unix:/var/run/php/php7.2-fpm.sock:", host: "task.local.frontend"
2019/07/04 16:36:49 [error] 961#961: *120 FastCGI sent in stderr: "PHP message: An Error occurred while handling another error:
yii\base\InvalidRouteException: Unable to resolve the request: site/error in /var/www/task.local/vendor/yiisoft/yii2/base/Controller.php:128
Stack trace:
#0 /var/www/task.local/vendor/yiisoft/yii2/base/Module.php(528): yii\base\Controller->runAction('error', Array)
#1 /var/www/task.local/vendor/yiisoft/yii2/web/ErrorHandler.php(108): yii\base\Module->runAction('site/error')
#2 /var/www/task.local/vendor/yiisoft/yii2/base/ErrorHandler.php(111): yii\web\ErrorHandler->renderException(Object(yii\web\NotFoundHttpException))
#3 [internal function]: yii\base\ErrorHandler->handleException(Object(yii\web\NotFoundHttpException))
#4 {main}
Previous exception:
yii\base\InvalidRouteException: Unable to resolve the request "logout". in /var/www/task.local/vendor/yiisoft/yii2/base/Module.php:537
Stack trace:
#0 /var/www/task.local/vendor/yiisoft/yii2/web/Application.php(103): yii\base\Module->runAction('logout', Array)
#1 /var/www/task.local/vendor/yiisoft/yii" while reading upstream, client: 127.0.0.1, server: task.local.frontend, request: "GET /logout HTTP/1.1", upstream: "fastcgi://unix:/var/run/php/php7.2-fpm.sock:", host: "task.local.frontend", referrer: "http://task.local.frontend/"
2019/07/04 18:27:27 [error] 967#967: *8 FastCGI sent in stderr: "PHP message: An Error occurred while handling another error:
yii\base\InvalidRouteException: Unable to resolve the request: site/error in /var/www/task.local/vendor/yiisoft/yii2/base/Controller.php:128
Stack trace:
#0 /var/www/task.local/vendor/yiisoft/yii2/base/Module.php(528): yii\base\Controller->runAction('error', Array)
#1 /var/www/task.local/vendor/yiisoft/yii2/web/ErrorHandler.php(108): yii\base\Module->runAction('site/error')
#2 /var/www/task.local/vendor/yiisoft/yii2/base/ErrorHandler.php(111): yii\web\ErrorHandler->renderException(Object(yii\web\NotFoundHttpException))
#3 [internal function]: yii\base\ErrorHandler->handleException(Object(yii\web\NotFoundHttpException))
#4 {main}
Previous exception:
yii\base\InvalidRouteException: Unable to resolve the request "/". in /var/www/task.local/vendor/yiisoft/yii2/base/Module.php:537
Stack trace:
#0 /var/www/task.local/vendor/yiisoft/yii2/web/Application.php(103): yii\base\Module->runAction('/', Array)
#1 /var/www/task.local/vendor/yiisoft/yii2/base/App" while reading upstream, client: 127.0.0.1, server: task.local.frontend, request: "GET // HTTP/1.1", upstream: "fastcgi://unix:/var/run/php/php7.2-fpm.sock:", host: "task.local.frontend"
2019/07/04 18:27:28 [error] 967#967: *8 FastCGI sent in stderr: "PHP message: An Error occurred while handling another error:
yii\base\InvalidRouteException: Unable to resolve the request: site/error in /var/www/task.local/vendor/yiisoft/yii2/base/Controller.php:128
Stack trace:
#0 /var/www/task.local/vendor/yiisoft/yii2/base/Module.php(528): yii\base\Controller->runAction('error', Array)
#1 /var/www/task.local/vendor/yiisoft/yii2/web/ErrorHandler.php(108): yii\base\Module->runAction('site/error')
#2 /var/www/task.local/vendor/yiisoft/yii2/base/ErrorHandler.php(111): yii\web\ErrorHandler->renderException(Object(yii\web\NotFoundHttpException))
#3 [internal function]: yii\base\ErrorHandler->handleException(Object(yii\web\NotFoundHttpException))
#4 {main}
Previous exception:
yii\base\InvalidRouteException: Unable to resolve the request "/". in /var/www/task.local/vendor/yiisoft/yii2/base/Module.php:537
Stack trace:
#0 /var/www/task.local/vendor/yiisoft/yii2/web/Application.php(103): yii\base\Module->runAction('/', Array)
#1 /var/www/task.local/vendor/yiisoft/yii2/base/App" while reading upstream, client: 127.0.0.1, server: task.local.frontend, request: "GET // HTTP/1.1", upstream: "fastcgi://unix:/var/run/php/php7.2-fpm.sock:", host: "task.local.frontend"
2019/07/04 18:39:56 [error] 967#967: *27 FastCGI sent in stderr: "PHP message: An Error occurred while handling another error:
yii\base\InvalidRouteException: Unable to resolve the request: site/error in /var/www/task.local/vendor/yiisoft/yii2/base/Controller.php:128
Stack trace:
#0 /var/www/task.local/vendor/yiisoft/yii2/base/Module.php(528): yii\base\Controller->runAction('error', Array)
#1 /var/www/task.local/vendor/yiisoft/yii2/web/ErrorHandler.php(108): yii\base\Module->runAction('site/error')
#2 /var/www/task.local/vendor/yiisoft/yii2/base/ErrorHandler.php(111): yii\web\ErrorHandler->renderException(Object(yii\web\NotFoundHttpException))
#3 [internal function]: yii\base\ErrorHandler->handleException(Object(yii\web\NotFoundHttpException))
#4 {main}
Previous exception:
yii\base\InvalidRouteException: Unable to resolve the request "cabinet/admin". in /var/www/task.local/vendor/yiisoft/yii2/base/Module.php:537
Stack trace:
#0 /var/www/task.local/vendor/yiisoft/yii2/web/Application.php(103): yii\base\Module->runAction('cabinet/admin', Array)
#1 /var/www/task.local/vend" while reading upstream, client: 127.0.0.1, server: task.local.frontend, request: "GET /cabinet/admin HTTP/1.1", upstream: "fastcgi://unix:/var/run/php/php7.2-fpm.sock:", host: "task.local.frontend", referrer: "http://task.local.frontend/login?error=%D0%9D%D0%B5%D0%BE%D0%B1%D1%85%D0%BE%D0%B4%D0%B8%D0%BC%D0%BE%20%D0%B7%D0%B0%D0%BF%D0%BE%D0%BB%D0%BD%D0%B8%D1%82%D1%8C%20%C2%ABLogin%C2%BB."
2019/07/04 18:40:10 [error] 967#967: *27 FastCGI sent in stderr: "PHP message: An Error occurred while handling another error:
yii\base\InvalidRouteException: Unable to resolve the request: site/error in /var/www/task.local/vendor/yiisoft/yii2/base/Controller.php:128
Stack trace:
#0 /var/www/task.local/vendor/yiisoft/yii2/base/Module.php(528): yii\base\Controller->runAction('error', Array)
#1 /var/www/task.local/vendor/yiisoft/yii2/web/ErrorHandler.php(108): yii\base\Module->runAction('site/error')
#2 /var/www/task.local/vendor/yiisoft/yii2/base/ErrorHandler.php(111): yii\web\ErrorHandler->renderException(Object(yii\web\NotFoundHttpException))
#3 [internal function]: yii\base\ErrorHandler->handleException(Object(yii\web\NotFoundHttpException))
#4 {main}
Previous exception:
yii\base\InvalidRouteException: Unable to resolve the request "cabinet/admin". in /var/www/task.local/vendor/yiisoft/yii2/base/Module.php:537
Stack trace:
#0 /var/www/task.local/vendor/yiisoft/yii2/web/Application.php(103): yii\base\Module->runAction('cabinet/admin', Array)
#1 /var/www/task.local/vend" while reading upstream, client: 127.0.0.1, server: task.local.frontend, request: "GET /cabinet/admin HTTP/1.1", upstream: "fastcgi://unix:/var/run/php/php7.2-fpm.sock:", host: "task.local.frontend", referrer: "http://task.local.frontend/login?error=%D0%92%D1%8B+%D0%BD%D0%B5%D0%B0%D0%B2%D1%82%D0%BE%D1%80%D0%B8%D0%B7%D0%B8%D1%80%D0%BE%D0%B2%D0%B0%D0%BD%D1%8B"
2019/07/04 18:40:12 [error] 967#967: *27 FastCGI sent in stderr: "PHP message: An Error occurred while handling another error:
yii\base\InvalidRouteException: Unable to resolve the request: site/error in /var/www/task.local/vendor/yiisoft/yii2/base/Controller.php:128
Stack trace:
#0 /var/www/task.local/vendor/yiisoft/yii2/base/Module.php(528): yii\base\Controller->runAction('error', Array)
#1 /var/www/task.local/vendor/yiisoft/yii2/web/ErrorHandler.php(108): yii\base\Module->runAction('site/error')
#2 /var/www/task.local/vendor/yiisoft/yii2/base/ErrorHandler.php(111): yii\web\ErrorHandler->renderException(Object(yii\web\NotFoundHttpException))
#3 [internal function]: yii\base\ErrorHandler->handleException(Object(yii\web\NotFoundHttpException))
#4 {main}
Previous exception:
yii\base\InvalidRouteException: Unable to resolve the request "cabinet/admin". in /var/www/task.local/vendor/yiisoft/yii2/base/Module.php:537
Stack trace:
#0 /var/www/task.local/vendor/yiisoft/yii2/web/Application.php(103): yii\base\Module->runAction('cabinet/admin', Array)
#1 /var/www/task.local/vend" while reading upstream, client: 127.0.0.1, server: task.local.frontend, request: "GET /cabinet/admin HTTP/1.1", upstream: "fastcgi://unix:/var/run/php/php7.2-fpm.sock:", host: "task.local.frontend"
2019/07/04 18:40:16 [error] 967#967: *27 FastCGI sent in stderr: "PHP message: An Error occurred while handling another error:
yii\base\InvalidRouteException: Unable to resolve the request: site/error in /var/www/task.local/vendor/yiisoft/yii2/base/Controller.php:128
Stack trace:
#0 /var/www/task.local/vendor/yiisoft/yii2/base/Module.php(528): yii\base\Controller->runAction('error', Array)
#1 /var/www/task.local/vendor/yiisoft/yii2/web/ErrorHandler.php(108): yii\base\Module->runAction('site/error')
#2 /var/www/task.local/vendor/yiisoft/yii2/base/ErrorHandler.php(111): yii\web\ErrorHandler->renderException(Object(yii\web\NotFoundHttpException))
#3 [internal function]: yii\base\ErrorHandler->handleException(Object(yii\web\NotFoundHttpException))
#4 {main}
Previous exception:
yii\base\InvalidRouteException: Unable to resolve the request "cabinet/admin". in /var/www/task.local/vendor/yiisoft/yii2/base/Module.php:537
Stack trace:
#0 /var/www/task.local/vendor/yiisoft/yii2/web/Application.php(103): yii\base\Module->runAction('cabinet/admin', Array)
#1 /var/www/task.local/vend" while reading upstream, client: 127.0.0.1, server: task.local.frontend, request: "GET /cabinet/admin HTTP/1.1", upstream: "fastcgi://unix:/var/run/php/php7.2-fpm.sock:", host: "task.local.frontend"
2019/07/04 18:40:21 [error] 967#967: *27 FastCGI sent in stderr: "PHP message: An Error occurred while handling another error:
yii\base\InvalidRouteException: Unable to resolve the request: site/error in /var/www/task.local/vendor/yiisoft/yii2/base/Controller.php:128
Stack trace:
#0 /var/www/task.local/vendor/yiisoft/yii2/base/Module.php(528): yii\base\Controller->runAction('error', Array)
#1 /var/www/task.local/vendor/yiisoft/yii2/web/ErrorHandler.php(108): yii\base\Module->runAction('site/error')
#2 /var/www/task.local/vendor/yiisoft/yii2/base/ErrorHandler.php(111): yii\web\ErrorHandler->renderException(Object(yii\web\NotFoundHttpException))
#3 [internal function]: yii\base\ErrorHandler->handleException(Object(yii\web\NotFoundHttpException))
#4 {main}
Previous exception:
yii\base\InvalidRouteException: Unable to resolve the request "cabinet/admin". in /var/www/task.local/vendor/yiisoft/yii2/base/Module.php:537
Stack trace:
#0 /var/www/task.local/vendor/yiisoft/yii2/web/Application.php(103): yii\base\Module->runAction('cabinet/admin', Array)
#1 /var/www/task.local/vend" while reading upstream, client: 127.0.0.1, server: task.local.frontend, request: "GET /cabinet/admin HTTP/1.1", upstream: "fastcgi://unix:/var/run/php/php7.2-fpm.sock:", host: "task.local.frontend"
2019/07/04 18:40:25 [error] 967#967: *27 FastCGI sent in stderr: "PHP message: An Error occurred while handling another error:
yii\base\InvalidRouteException: Unable to resolve the request: site/error in /var/www/task.local/vendor/yiisoft/yii2/base/Controller.php:128
Stack trace:
#0 /var/www/task.local/vendor/yiisoft/yii2/base/Module.php(528): yii\base\Controller->runAction('error', Array)
#1 /var/www/task.local/vendor/yiisoft/yii2/web/ErrorHandler.php(108): yii\base\Module->runAction('site/error')
#2 /var/www/task.local/vendor/yiisoft/yii2/base/ErrorHandler.php(111): yii\web\ErrorHandler->renderException(Object(yii\web\NotFoundHttpException))
#3 [internal function]: yii\base\ErrorHandler->handleException(Object(yii\web\NotFoundHttpException))
#4 {main}
Previous exception:
yii\base\InvalidRouteException: Unable to resolve the request "cabinet/admin". in /var/www/task.local/vendor/yiisoft/yii2/base/Module.php:537
Stack trace:
#0 /var/www/task.local/vendor/yiisoft/yii2/web/Application.php(103): yii\base\Module->runAction('cabinet/admin', Array)
#1 /var/www/task.local/vend" while reading upstream, client: 127.0.0.1, server: task.local.frontend, request: "GET /cabinet/admin HTTP/1.1", upstream: "fastcgi://unix:/var/run/php/php7.2-fpm.sock:", host: "task.local.frontend"
2019/07/04 18:41:08 [error] 967#967: *27 FastCGI sent in stderr: "PHP message: An Error occurred while handling another error:
yii\base\InvalidRouteException: Unable to resolve the request: site/error in /var/www/task.local/vendor/yiisoft/yii2/base/Controller.php:128
Stack trace:
#0 /var/www/task.local/vendor/yiisoft/yii2/base/Module.php(528): yii\base\Controller->runAction('error', Array)
#1 /var/www/task.local/vendor/yiisoft/yii2/web/ErrorHandler.php(108): yii\base\Module->runAction('site/error')
#2 /var/www/task.local/vendor/yiisoft/yii2/base/ErrorHandler.php(111): yii\web\ErrorHandler->renderException(Object(yii\web\NotFoundHttpException))
#3 [internal function]: yii\base\ErrorHandler->handleException(Object(yii\web\NotFoundHttpException))
#4 {main}
Previous exception:
yii\base\InvalidRouteException: Unable to resolve the request "cabinet/admin". in /var/www/task.local/vendor/yiisoft/yii2/base/Module.php:537
Stack trace:
#0 /var/www/task.local/vendor/yiisoft/yii2/web/Application.php(103): yii\base\Module->runAction('cabinet/admin', Array)
#1 /var/www/task.local/vend" while reading upstream, client: 127.0.0.1, server: task.local.frontend, request: "GET /cabinet/admin HTTP/1.1", upstream: "fastcgi://unix:/var/run/php/php7.2-fpm.sock:", host: "task.local.frontend"
2019/07/04 18:41:09 [error] 967#967: *27 FastCGI sent in stderr: "PHP message: An Error occurred while handling another error:
yii\base\InvalidRouteException: Unable to resolve the request: site/error in /var/www/task.local/vendor/yiisoft/yii2/base/Controller.php:128
Stack trace:
#0 /var/www/task.local/vendor/yiisoft/yii2/base/Module.php(528): yii\base\Controller->runAction('error', Array)
#1 /var/www/task.local/vendor/yiisoft/yii2/web/ErrorHandler.php(108): yii\base\Module->runAction('site/error')
#2 /var/www/task.local/vendor/yiisoft/yii2/base/ErrorHandler.php(111): yii\web\ErrorHandler->renderException(Object(yii\web\NotFoundHttpException))
#3 [internal function]: yii\base\ErrorHandler->handleException(Object(yii\web\NotFoundHttpException))
#4 {main}
Previous exception:
yii\base\InvalidRouteException: Unable to resolve the request "/". in /var/www/task.local/vendor/yiisoft/yii2/base/Module.php:537
Stack trace:
#0 /var/www/task.local/vendor/yiisoft/yii2/web/Application.php(103): yii\base\Module->runAction('/', Array)
#1 /var/www/task.local/vendor/yiisoft/yii2/base/App" while reading upstream, client: 127.0.0.1, server: task.local.frontend, request: "GET // HTTP/1.1", upstream: "fastcgi://unix:/var/run/php/php7.2-fpm.sock:", host: "task.local.frontend"
2019/07/05 09:01:48 [error] 983#983: *1 FastCGI sent in stderr: "PHP message: An Error occurred while handling another error:
yii\base\InvalidRouteException: Unable to resolve the request: site/error in /var/www/task.local/vendor/yiisoft/yii2/base/Controller.php:128
Stack trace:
#0 /var/www/task.local/vendor/yiisoft/yii2/base/Module.php(528): yii\base\Controller->runAction('error', Array)
#1 /var/www/task.local/vendor/yiisoft/yii2/web/ErrorHandler.php(108): yii\base\Module->runAction('site/error')
#2 /var/www/task.local/vendor/yiisoft/yii2/base/ErrorHandler.php(111): yii\web\ErrorHandler->renderException(Object(yii\web\NotFoundHttpException))
#3 [internal function]: yii\base\ErrorHandler->handleException(Object(yii\web\NotFoundHttpException))
#4 {main}
Previous exception:
yii\base\InvalidRouteException: Unable to resolve the request "web/style/css/all.css". in /var/www/task.local/vendor/yiisoft/yii2/base/Module.php:537
Stack trace:
#0 /var/www/task.local/vendor/yiisoft/yii2/web/Application.php(103): yii\base\Module->runAction('web/style/css/a...', Array)
#1 /var/www/ta" while reading upstream, client: 127.0.0.1, server: task.local.frontend, request: "GET /web/style/css/all.css HTTP/1.1", upstream: "fastcgi://unix:/var/run/php/php7.2-fpm.sock:", host: "task.local.frontend", referrer: "http://task.local.frontend/login?error=%D0%92%D1%8B+%D0%BD%D0%B5%D0%B0%D0%B2%D1%82%D0%BE%D1%80%D0%B8%D0%B7%D0%B8%D1%80%D0%BE%D0%B2%D0%B0%D0%BD%D1%8B"
2019/07/05 09:01:48 [error] 983#983: *9 FastCGI sent in stderr: "PHP message: An Error occurred while handling another error:
yii\base\InvalidRouteException: Unable to resolve the request: site/error in /var/www/task.local/vendor/yiisoft/yii2/base/Controller.php:128
Stack trace:
#0 /var/www/task.local/vendor/yiisoft/yii2/base/Module.php(528): yii\base\Controller->runAction('error', Array)
#1 /var/www/task.local/vendor/yiisoft/yii2/web/ErrorHandler.php(108): yii\base\Module->runAction('site/error')
#2 /var/www/task.local/vendor/yiisoft/yii2/base/ErrorHandler.php(111): yii\web\ErrorHandler->renderException(Object(yii\web\NotFoundHttpException))
#3 [internal function]: yii\base\ErrorHandler->handleException(Object(yii\web\NotFoundHttpException))
#4 {main}
Previous exception:
yii\base\InvalidRouteException: Unable to resolve the request "web/style/style.css". in /var/www/task.local/vendor/yiisoft/yii2/base/Module.php:537
Stack trace:
#0 /var/www/task.local/vendor/yiisoft/yii2/web/Application.php(103): yii\base\Module->runAction('web/style/style...', Array)
#1 /var/www/task" while reading upstream, client: 127.0.0.1, server: task.local.frontend, request: "GET /web/style/style.css HTTP/1.1", upstream: "fastcgi://unix:/var/run/php/php7.2-fpm.sock:", host: "task.local.frontend", referrer: "http://task.local.frontend/login?error=%D0%92%D1%8B+%D0%BD%D0%B5%D0%B0%D0%B2%D1%82%D0%BE%D1%80%D0%B8%D0%B7%D0%B8%D1%80%D0%BE%D0%B2%D0%B0%D0%BD%D1%8B"
2019/07/05 09:02:03 [error] 983#983: *9 FastCGI sent in stderr: "PHP message: An Error occurred while handling another error:
yii\base\InvalidRouteException: Unable to resolve the request: site/error in /var/www/task.local/vendor/yiisoft/yii2/base/Controller.php:128
Stack trace:
#0 /var/www/task.local/vendor/yiisoft/yii2/base/Module.php(528): yii\base\Controller->runAction('error', Array)
#1 /var/www/task.local/vendor/yiisoft/yii2/web/ErrorHandler.php(108): yii\base\Module->runAction('site/error')
#2 /var/www/task.local/vendor/yiisoft/yii2/base/ErrorHandler.php(111): yii\web\ErrorHandler->renderException(Object(yii\web\NotFoundHttpException))
#3 [internal function]: yii\base\ErrorHandler->handleException(Object(yii\web\NotFoundHttpException))
#4 {main}
Previous exception:
yii\base\InvalidRouteException: Unable to resolve the request "web/style/css/all.css". in /var/www/task.local/vendor/yiisoft/yii2/base/Module.php:537
Stack trace:
#0 /var/www/task.local/vendor/yiisoft/yii2/web/Application.php(103): yii\base\Module->runAction('web/style/css/a...', Array)
#1 /var/www/ta" while reading upstream, client: 127.0.0.1, server: task.local.frontend, request: "GET /web/style/css/all.css HTTP/1.1", upstream: "fastcgi://unix:/var/run/php/php7.2-fpm.sock:", host: "task.local.frontend", referrer: "http://task.local.frontend/login?error=%D0%92%D1%8B+%D0%BD%D0%B5%D0%B0%D0%B2%D1%82%D0%BE%D1%80%D0%B8%D0%B7%D0%B8%D1%80%D0%BE%D0%B2%D0%B0%D0%BD%D1%8B"
2019/07/05 09:02:03 [error] 983#983: *8 FastCGI sent in stderr: "PHP message: An Error occurred while handling another error:
yii\base\InvalidRouteException: Unable to resolve the request: site/error in /var/www/task.local/vendor/yiisoft/yii2/base/Controller.php:128
Stack trace:
#0 /var/www/task.local/vendor/yiisoft/yii2/base/Module.php(528): yii\base\Controller->runAction('error', Array)
#1 /var/www/task.local/vendor/yiisoft/yii2/web/ErrorHandler.php(108): yii\base\Module->runAction('site/error')
#2 /var/www/task.local/vendor/yiisoft/yii2/base/ErrorHandler.php(111): yii\web\ErrorHandler->renderException(Object(yii\web\NotFoundHttpException))
#3 [internal function]: yii\base\ErrorHandler->handleException(Object(yii\web\NotFoundHttpException))
#4 {main}
Previous exception:
yii\base\InvalidRouteException: Unable to resolve the request "web/style/style.css". in /var/www/task.local/vendor/yiisoft/yii2/base/Module.php:537
Stack trace:
#0 /var/www/task.local/vendor/yiisoft/yii2/web/Application.php(103): yii\base\Module->runAction('web/style/style...', Array)
#1 /var/www/task" while reading upstream, client: 127.0.0.1, server: task.local.frontend, request: "GET /web/style/style.css HTTP/1.1", upstream: "fastcgi://unix:/var/run/php/php7.2-fpm.sock:", host: "task.local.frontend", referrer: "http://task.local.frontend/login?error=%D0%92%D1%8B+%D0%BD%D0%B5%D0%B0%D0%B2%D1%82%D0%BE%D1%80%D0%B8%D0%B7%D0%B8%D1%80%D0%BE%D0%B2%D0%B0%D0%BD%D1%8B"
2019/07/05 09:02:14 [error] 983#983: *1 FastCGI sent in stderr: "PHP message: An Error occurred while handling another error:
yii\base\InvalidRouteException: Unable to resolve the request: site/error in /var/www/task.local/vendor/yiisoft/yii2/base/Controller.php:128
Stack trace:
#0 /var/www/task.local/vendor/yiisoft/yii2/base/Module.php(528): yii\base\Controller->runAction('error', Array)
#1 /var/www/task.local/vendor/yiisoft/yii2/web/ErrorHandler.php(108): yii\base\Module->runAction('site/error')
#2 /var/www/task.local/vendor/yiisoft/yii2/base/ErrorHandler.php(111): yii\web\ErrorHandler->renderException(Object(yii\web\NotFoundHttpException))
#3 [internal function]: yii\base\ErrorHandler->handleException(Object(yii\web\NotFoundHttpException))
#4 {main}
Previous exception:
yii\base\InvalidRouteException: Unable to resolve the request "cabinet/admin". in /var/www/task.local/vendor/yiisoft/yii2/base/Module.php:537
Stack trace:
#0 /var/www/task.local/vendor/yiisoft/yii2/web/Application.php(103): yii\base\Module->runAction('cabinet/admin', Array)
#1 /var/www/task.local/vend" while reading upstream, client: 127.0.0.1, server: task.local.frontend, request: "GET /cabinet/admin HTTP/1.1", upstream: "fastcgi://unix:/var/run/php/php7.2-fpm.sock:", host: "task.local.frontend", referrer: "http://task.local.frontend/login?error=%D0%92%D1%8B+%D0%BD%D0%B5%D0%B0%D0%B2%D1%82%D0%BE%D1%80%D0%B8%D0%B7%D0%B8%D1%80%D0%BE%D0%B2%D0%B0%D0%BD%D1%8B"
2019/07/05 09:02:16 [error] 983#983: *8 FastCGI sent in stderr: "PHP message: An Error occurred while handling another error:
yii\base\InvalidRouteException: Unable to resolve the request: site/error in /var/www/task.local/vendor/yiisoft/yii2/base/Controller.php:128
Stack trace:
#0 /var/www/task.local/vendor/yiisoft/yii2/base/Module.php(528): yii\base\Controller->runAction('error', Array)
#1 /var/www/task.local/vendor/yiisoft/yii2/web/ErrorHandler.php(108): yii\base\Module->runAction('site/error')
#2 /var/www/task.local/vendor/yiisoft/yii2/base/ErrorHandler.php(111): yii\web\ErrorHandler->renderException(Object(yii\web\NotFoundHttpException))
#3 [internal function]: yii\base\ErrorHandler->handleException(Object(yii\web\NotFoundHttpException))
#4 {main}
Previous exception:
yii\base\InvalidRouteException: Unable to resolve the request "web/style/css/all.css". in /var/www/task.local/vendor/yiisoft/yii2/base/Module.php:537
Stack trace:
#0 /var/www/task.local/vendor/yiisoft/yii2/web/Application.php(103): yii\base\Module->runAction('web/style/css/a...', Array)
#1 /var/www/ta" while reading upstream, client: 127.0.0.1, server: task.local.frontend, request: "GET /web/style/css/all.css HTTP/1.1", upstream: "fastcgi://unix:/var/run/php/php7.2-fpm.sock:", host: "task.local.frontend", referrer: "http://task.local.frontend/"
2019/07/05 09:02:16 [error] 983#983: *7 FastCGI sent in stderr: "PHP message: An Error occurred while handling another error:
yii\base\InvalidRouteException: Unable to resolve the request: site/error in /var/www/task.local/vendor/yiisoft/yii2/base/Controller.php:128
Stack trace:
#0 /var/www/task.local/vendor/yiisoft/yii2/base/Module.php(528): yii\base\Controller->runAction('error', Array)
#1 /var/www/task.local/vendor/yiisoft/yii2/web/ErrorHandler.php(108): yii\base\Module->runAction('site/error')
#2 /var/www/task.local/vendor/yiisoft/yii2/base/ErrorHandler.php(111): yii\web\ErrorHandler->renderException(Object(yii\web\NotFoundHttpException))
#3 [internal function]: yii\base\ErrorHandler->handleException(Object(yii\web\NotFoundHttpException))
#4 {main}
Previous exception:
yii\base\InvalidRouteException: Unable to resolve the request "web/style/style.css". in /var/www/task.local/vendor/yiisoft/yii2/base/Module.php:537
Stack trace:
#0 /var/www/task.local/vendor/yiisoft/yii2/web/Application.php(103): yii\base\Module->runAction('web/style/style...', Array)
#1 /var/www/task" while reading upstream, client: 127.0.0.1, server: task.local.frontend, request: "GET /web/style/style.css HTTP/1.1", upstream: "fastcgi://unix:/var/run/php/php7.2-fpm.sock:", host: "task.local.frontend", referrer: "http://task.local.frontend/"
2019/07/05 09:02:20 [error] 983#983: *8 FastCGI sent in stderr: "PHP message: An Error occurred while handling another error:
yii\base\InvalidRouteException: Unable to resolve the request: site/error in /var/www/task.local/vendor/yiisoft/yii2/base/Controller.php:128
Stack trace:
#0 /var/www/task.local/vendor/yiisoft/yii2/base/Module.php(528): yii\base\Controller->runAction('error', Array)
#1 /var/www/task.local/vendor/yiisoft/yii2/web/ErrorHandler.php(108): yii\base\Module->runAction('site/error')
#2 /var/www/task.local/vendor/yiisoft/yii2/base/ErrorHandler.php(111): yii\web\ErrorHandler->renderException(Object(yii\web\NotFoundHttpException))
#3 [internal function]: yii\base\ErrorHandler->handleException(Object(yii\web\NotFoundHttpException))
#4 {main}
Previous exception:
yii\base\InvalidRouteException: Unable to resolve the request "web/style/css/all.css". in /var/www/task.local/vendor/yiisoft/yii2/base/Module.php:537
Stack trace:
#0 /var/www/task.local/vendor/yiisoft/yii2/web/Application.php(103): yii\base\Module->runAction('web/style/css/a...', Array)
#1 /var/www/ta" while reading upstream, client: 127.0.0.1, server: task.local.frontend, request: "GET /web/style/css/all.css HTTP/1.1", upstream: "fastcgi://unix:/var/run/php/php7.2-fpm.sock:", host: "task.local.frontend", referrer: "http://task.local.frontend/"
2019/07/05 09:02:20 [error] 983#983: *7 FastCGI sent in stderr: "PHP message: An Error occurred while handling another error:
yii\base\InvalidRouteException: Unable to resolve the request: site/error in /var/www/task.local/vendor/yiisoft/yii2/base/Controller.php:128
Stack trace:
#0 /var/www/task.local/vendor/yiisoft/yii2/base/Module.php(528): yii\base\Controller->runAction('error', Array)
#1 /var/www/task.local/vendor/yiisoft/yii2/web/ErrorHandler.php(108): yii\base\Module->runAction('site/error')
#2 /var/www/task.local/vendor/yiisoft/yii2/base/ErrorHandler.php(111): yii\web\ErrorHandler->renderException(Object(yii\web\NotFoundHttpException))
#3 [internal function]: yii\base\ErrorHandler->handleException(Object(yii\web\NotFoundHttpException))
#4 {main}
Previous exception:
yii\base\InvalidRouteException: Unable to resolve the request "web/style/style.css". in /var/www/task.local/vendor/yiisoft/yii2/base/Module.php:537
Stack trace:
#0 /var/www/task.local/vendor/yiisoft/yii2/web/Application.php(103): yii\base\Module->runAction('web/style/style...', Array)
#1 /var/www/task" while reading upstream, client: 127.0.0.1, server: task.local.frontend, request: "GET /web/style/style.css HTTP/1.1", upstream: "fastcgi://unix:/var/run/php/php7.2-fpm.sock:", host: "task.local.frontend", referrer: "http://task.local.frontend/"
2019/07/05 09:04:05 [error] 983#983: *30 FastCGI sent in stderr: "PHP message: An Error occurred while handling another error:
yii\base\InvalidRouteException: Unable to resolve the request: site/error in /var/www/task.local/vendor/yiisoft/yii2/base/Controller.php:128
Stack trace:
#0 /var/www/task.local/vendor/yiisoft/yii2/base/Module.php(528): yii\base\Controller->runAction('error', Array)
#1 /var/www/task.local/vendor/yiisoft/yii2/web/ErrorHandler.php(108): yii\base\Module->runAction('site/error')
#2 /var/www/task.local/vendor/yiisoft/yii2/base/ErrorHandler.php(111): yii\web\ErrorHandler->renderException(Object(yii\web\NotFoundHttpException))
#3 [internal function]: yii\base\ErrorHandler->handleException(Object(yii\web\NotFoundHttpException))
#4 {main}
Previous exception:
yii\base\InvalidRouteException: Unable to resolve the request "web/css/css/all.css". in /var/www/task.local/vendor/yiisoft/yii2/base/Module.php:537
Stack trace:
#0 /var/www/task.local/vendor/yiisoft/yii2/web/Application.php(103): yii\base\Module->runAction('web/css/css/all...', Array)
#1 /var/www/task" while reading upstream, client: 127.0.0.1, server: task.local.frontend, request: "GET /web/css/css/all.css HTTP/1.1", upstream: "fastcgi://unix:/var/run/php/php7.2-fpm.sock:", host: "task.local.frontend", referrer: "http://task.local.frontend/"
2019/07/05 09:04:05 [error] 983#983: *33 FastCGI sent in stderr: "PHP message: An Error occurred while handling another error:
yii\base\InvalidRouteException: Unable to resolve the request: site/error in /var/www/task.local/vendor/yiisoft/yii2/base/Controller.php:128
Stack trace:
#0 /var/www/task.local/vendor/yiisoft/yii2/base/Module.php(528): yii\base\Controller->runAction('error', Array)
#1 /var/www/task.local/vendor/yiisoft/yii2/web/ErrorHandler.php(108): yii\base\Module->runAction('site/error')
#2 /var/www/task.local/vendor/yiisoft/yii2/base/ErrorHandler.php(111): yii\web\ErrorHandler->renderException(Object(yii\web\NotFoundHttpException))
#3 [internal function]: yii\base\ErrorHandler->handleException(Object(yii\web\NotFoundHttpException))
#4 {main}
Previous exception:
yii\base\InvalidRouteException: Unable to resolve the request "web/css/style.css". in /var/www/task.local/vendor/yiisoft/yii2/base/Module.php:537
Stack trace:
#0 /var/www/task.local/vendor/yiisoft/yii2/web/Application.php(103): yii\base\Module->runAction('web/css/style.c...', Array)
#1 /var/www/task.l" while reading upstream, client: 127.0.0.1, server: task.local.frontend, request: "GET /web/css/style.css HTTP/1.1", upstream: "fastcgi://unix:/var/run/php/php7.2-fpm.sock:", host: "task.local.frontend", referrer: "http://task.local.frontend/"
2019/07/05 09:04:20 [error] 983#983: *33 FastCGI sent in stderr: "PHP message: An Error occurred while handling another error:
yii\base\InvalidRouteException: Unable to resolve the request: site/error in /var/www/task.local/vendor/yiisoft/yii2/base/Controller.php:128
Stack trace:
#0 /var/www/task.local/vendor/yiisoft/yii2/base/Module.php(528): yii\base\Controller->runAction('error', Array)
#1 /var/www/task.local/vendor/yiisoft/yii2/web/ErrorHandler.php(108): yii\base\Module->runAction('site/error')
#2 /var/www/task.local/vendor/yiisoft/yii2/base/ErrorHandler.php(111): yii\web\ErrorHandler->renderException(Object(yii\web\NotFoundHttpException))
#3 [internal function]: yii\base\ErrorHandler->handleException(Object(yii\web\NotFoundHttpException))
#4 {main}
Previous exception:
yii\base\InvalidRouteException: Unable to resolve the request "web/css/css/all.css". in /var/www/task.local/vendor/yiisoft/yii2/base/Module.php:537
Stack trace:
#0 /var/www/task.local/vendor/yiisoft/yii2/web/Application.php(103): yii\base\Module->runAction('web/css/css/all...', Array)
#1 /var/www/task" while reading upstream, client: 127.0.0.1, server: task.local.frontend, request: "GET /web/css/css/all.css HTTP/1.1", upstream: "fastcgi://unix:/var/run/php/php7.2-fpm.sock:", host: "task.local.frontend", referrer: "http://task.local.frontend/"
2019/07/05 09:04:20 [error] 983#983: *35 FastCGI sent in stderr: "PHP message: An Error occurred while handling another error:
yii\base\InvalidRouteException: Unable to resolve the request: site/error in /var/www/task.local/vendor/yiisoft/yii2/base/Controller.php:128
Stack trace:
#0 /var/www/task.local/vendor/yiisoft/yii2/base/Module.php(528): yii\base\Controller->runAction('error', Array)
#1 /var/www/task.local/vendor/yiisoft/yii2/web/ErrorHandler.php(108): yii\base\Module->runAction('site/error')
#2 /var/www/task.local/vendor/yiisoft/yii2/base/ErrorHandler.php(111): yii\web\ErrorHandler->renderException(Object(yii\web\NotFoundHttpException))
#3 [internal function]: yii\base\ErrorHandler->handleException(Object(yii\web\NotFoundHttpException))
#4 {main}
Previous exception:
yii\base\InvalidRouteException: Unable to resolve the request "web/css/style.css". in /var/www/task.local/vendor/yiisoft/yii2/base/Module.php:537
Stack trace:
#0 /var/www/task.local/vendor/yiisoft/yii2/web/Application.php(103): yii\base\Module->runAction('web/css/style.c...', Array)
#1 /var/www/task.l" while reading upstream, client: 127.0.0.1, server: task.local.frontend, request: "GET /web/css/style.css HTTP/1.1", upstream: "fastcgi://unix:/var/run/php/php7.2-fpm.sock:", host: "task.local.frontend", referrer: "http://task.local.frontend/"
2019/07/05 09:05:59 [error] 983#983: *42 FastCGI sent in stderr: "PHP message: An Error occurred while handling another error:
yii\base\InvalidRouteException: Unable to resolve the request: site/error in /var/www/task.local/vendor/yiisoft/yii2/base/Controller.php:128
Stack trace:
#0 /var/www/task.local/vendor/yiisoft/yii2/base/Module.php(528): yii\base\Controller->runAction('error', Array)
#1 /var/www/task.local/vendor/yiisoft/yii2/web/ErrorHandler.php(108): yii\base\Module->runAction('site/error')
#2 /var/www/task.local/vendor/yiisoft/yii2/base/ErrorHandler.php(111): yii\web\ErrorHandler->renderException(Object(yii\web\NotFoundHttpException))
#3 [internal function]: yii\base\ErrorHandler->handleException(Object(yii\web\NotFoundHttpException))
#4 {main}
Previous exception:
yii\base\InvalidRouteException: Unable to resolve the request "web/css/css/all.css". in /var/www/task.local/vendor/yiisoft/yii2/base/Module.php:537
Stack trace:
#0 /var/www/task.local/vendor/yiisoft/yii2/web/Application.php(103): yii\base\Module->runAction('web/css/css/all...', Array)
#1 /var/www/task" while reading upstream, client: 127.0.0.1, server: task.local.frontend, request: "GET /web/css/css/all.css HTTP/1.1", upstream: "fastcgi://unix:/var/run/php/php7.2-fpm.sock:", host: "task.local.frontend", referrer: "http://task.local.frontend/"
2019/07/05 09:06:00 [error] 983#983: *46 FastCGI sent in stderr: "PHP message: An Error occurred while handling another error:
yii\base\InvalidRouteException: Unable to resolve the request: site/error in /var/www/task.local/vendor/yiisoft/yii2/base/Controller.php:128
Stack trace:
#0 /var/www/task.local/vendor/yiisoft/yii2/base/Module.php(528): yii\base\Controller->runAction('error', Array)
#1 /var/www/task.local/vendor/yiisoft/yii2/web/ErrorHandler.php(108): yii\base\Module->runAction('site/error')
#2 /var/www/task.local/vendor/yiisoft/yii2/base/ErrorHandler.php(111): yii\web\ErrorHandler->renderException(Object(yii\web\NotFoundHttpException))
#3 [internal function]: yii\base\ErrorHandler->handleException(Object(yii\web\NotFoundHttpException))
#4 {main}
Previous exception:
yii\base\InvalidRouteException: Unable to resolve the request "web/css/style.css". in /var/www/task.local/vendor/yiisoft/yii2/base/Module.php:537
Stack trace:
#0 /var/www/task.local/vendor/yiisoft/yii2/web/Application.php(103): yii\base\Module->runAction('web/css/style.c...', Array)
#1 /var/www/task.l" while reading upstream, client: 127.0.0.1, server: task.local.frontend, request: "GET /web/css/style.css HTTP/1.1", upstream: "fastcgi://unix:/var/run/php/php7.2-fpm.sock:", host: "task.local.frontend", referrer: "http://task.local.frontend/"
2019/07/05 09:06:24 [error] 983#983: *46 FastCGI sent in stderr: "PHP message: An Error occurred while handling another error:
yii\base\InvalidRouteException: Unable to resolve the request: site/error in /var/www/task.local/vendor/yiisoft/yii2/base/Controller.php:128
Stack trace:
#0 /var/www/task.local/vendor/yiisoft/yii2/base/Module.php(528): yii\base\Controller->runAction('error', Array)
#1 /var/www/task.local/vendor/yiisoft/yii2/web/ErrorHandler.php(108): yii\base\Module->runAction('site/error')
#2 /var/www/task.local/vendor/yiisoft/yii2/base/ErrorHandler.php(111): yii\web\ErrorHandler->renderException(Object(yii\web\NotFoundHttpException))
#3 [internal function]: yii\base\ErrorHandler->handleException(Object(yii\web\NotFoundHttpException))
#4 {main}
Previous exception:
yii\base\InvalidRouteException: Unable to resolve the request "frontend/web/css/css/all.css". in /var/www/task.local/vendor/yiisoft/yii2/base/Module.php:537
Stack trace:
#0 /var/www/task.local/vendor/yiisoft/yii2/web/Application.php(103): yii\base\Module->runAction('frontend/web/cs...', Array)
#1 /var" while reading upstream, client: 127.0.0.1, server: task.local.frontend, request: "GET /frontend/web/css/css/all.css HTTP/1.1", upstream: "fastcgi://unix:/var/run/php/php7.2-fpm.sock:", host: "task.local.frontend", referrer: "http://task.local.frontend/"
2019/07/05 09:06:24 [error] 983#983: *45 FastCGI sent in stderr: "PHP message: An Error occurred while handling another error:
yii\base\InvalidRouteException: Unable to resolve the request: site/error in /var/www/task.local/vendor/yiisoft/yii2/base/Controller.php:128
Stack trace:
#0 /var/www/task.local/vendor/yiisoft/yii2/base/Module.php(528): yii\base\Controller->runAction('error', Array)
#1 /var/www/task.local/vendor/yiisoft/yii2/web/ErrorHandler.php(108): yii\base\Module->runAction('site/error')
#2 /var/www/task.local/vendor/yiisoft/yii2/base/ErrorHandler.php(111): yii\web\ErrorHandler->renderException(Object(yii\web\NotFoundHttpException))
#3 [internal function]: yii\base\ErrorHandler->handleException(Object(yii\web\NotFoundHttpException))
#4 {main}
Previous exception:
yii\base\InvalidRouteException: Unable to resolve the request "frontend/web/css/style.css". in /var/www/task.local/vendor/yiisoft/yii2/base/Module.php:537
Stack trace:
#0 /var/www/task.local/vendor/yiisoft/yii2/web/Application.php(103): yii\base\Module->runAction('frontend/web/cs...', Array)
#1 /var/w" while reading upstream, client: 127.0.0.1, server: task.local.frontend, request: "GET /frontend/web/css/style.css HTTP/1.1", upstream: "fastcgi://unix:/var/run/php/php7.2-fpm.sock:", host: "task.local.frontend", referrer: "http://task.local.frontend/"
2019/07/05 09:08:54 [error] 983#983: *60 FastCGI sent in stderr: "PHP message: An Error occurred while handling another error:
yii\base\InvalidRouteException: Unable to resolve the request: site/error in /var/www/task.local/vendor/yiisoft/yii2/base/Controller.php:128
Stack trace:
#0 /var/www/task.local/vendor/yiisoft/yii2/base/Module.php(528): yii\base\Controller->runAction('error', Array)
#1 /var/www/task.local/vendor/yiisoft/yii2/web/ErrorHandler.php(108): yii\base\Module->runAction('site/error')
#2 /var/www/task.local/vendor/yiisoft/yii2/base/ErrorHandler.php(111): yii\web\ErrorHandler->renderException(Object(yii\web\NotFoundHttpException))
#3 [internal function]: yii\base\ErrorHandler->handleException(Object(yii\web\NotFoundHttpException))
#4 {main}
Previous exception:
yii\base\InvalidRouteException: Unable to resolve the request "frontend/web/css/css/all.css". in /var/www/task.local/vendor/yiisoft/yii2/base/Module.php:537
Stack trace:
#0 /var/www/task.local/vendor/yiisoft/yii2/web/Application.php(103): yii\base\Module->runAction('frontend/web/cs...', Array)
#1 /var" while reading upstream, client: 127.0.0.1, server: task.local.frontend, request: "GET /frontend/web/css/css/all.css HTTP/1.1", upstream: "fastcgi://unix:/var/run/php/php7.2-fpm.sock:", host: "task.local.frontend", referrer: "http://task.local.frontend/"
2019/07/05 09:08:54 [error] 983#983: *63 FastCGI sent in stderr: "PHP message: An Error occurred while handling another error:
yii\base\InvalidRouteException: Unable to resolve the request: site/error in /var/www/task.local/vendor/yiisoft/yii2/base/Controller.php:128
Stack trace:
#0 /var/www/task.local/vendor/yiisoft/yii2/base/Module.php(528): yii\base\Controller->runAction('error', Array)
#1 /var/www/task.local/vendor/yiisoft/yii2/web/ErrorHandler.php(108): yii\base\Module->runAction('site/error')
#2 /var/www/task.local/vendor/yiisoft/yii2/base/ErrorHandler.php(111): yii\web\ErrorHandler->renderException(Object(yii\web\NotFoundHttpException))
#3 [internal function]: yii\base\ErrorHandler->handleException(Object(yii\web\NotFoundHttpException))
#4 {main}
Previous exception:
yii\base\InvalidRouteException: Unable to resolve the request "frontend/web/css/style.css". in /var/www/task.local/vendor/yiisoft/yii2/base/Module.php:537
Stack trace:
#0 /var/www/task.local/vendor/yiisoft/yii2/web/Application.php(103): yii\base\Module->runAction('frontend/web/cs...', Array)
#1 /var/w" while reading upstream, client: 127.0.0.1, server: task.local.frontend, request: "GET /frontend/web/css/style.css HTTP/1.1", upstream: "fastcgi://unix:/var/run/php/php7.2-fpm.sock:", host: "task.local.frontend", referrer: "http://task.local.frontend/"
2019/07/05 09:12:30 [error] 983#983: *67 FastCGI sent in stderr: "PHP message: An Error occurred while handling another error:
yii\base\InvalidRouteException: Unable to resolve the request: site/error in /var/www/task.local/vendor/yiisoft/yii2/base/Controller.php:128
Stack trace:
#0 /var/www/task.local/vendor/yiisoft/yii2/base/Module.php(528): yii\base\Controller->runAction('error', Array)
#1 /var/www/task.local/vendor/yiisoft/yii2/web/ErrorHandler.php(108): yii\base\Module->runAction('site/error')
#2 /var/www/task.local/vendor/yiisoft/yii2/base/ErrorHandler.php(111): yii\web\ErrorHandler->renderException(Object(yii\web\NotFoundHttpException))
#3 [internal function]: yii\base\ErrorHandler->handleException(Object(yii\web\NotFoundHttpException))
#4 {main}
Previous exception:
yii\base\InvalidRouteException: Unable to resolve the request "frontend/web/css/css/all.css". in /var/www/task.local/vendor/yiisoft/yii2/base/Module.php:537
Stack trace:
#0 /var/www/task.local/vendor/yiisoft/yii2/web/Application.php(103): yii\base\Module->runAction('frontend/web/cs...', Array)
#1 /var" while reading upstream, client: 127.0.0.1, server: task.local.frontend, request: "GET /frontend/web/css/css/all.css HTTP/1.1", upstream: "fastcgi://unix:/var/run/php/php7.2-fpm.sock:", host: "task.local.frontend", referrer: "http://task.local.frontend/login?error=%D0%92%D1%8B+%D0%BD%D0%B5%D0%B0%D0%B2%D1%82%D0%BE%D1%80%D0%B8%D0%B7%D0%B8%D1%80%D0%BE%D0%B2%D0%B0%D0%BD%D1%8B"
2019/07/05 09:12:30 [error] 983#983: *71 FastCGI sent in stderr: "PHP message: An Error occurred while handling another error:
yii\base\InvalidRouteException: Unable to resolve the request: site/error in /var/www/task.local/vendor/yiisoft/yii2/base/Controller.php:128
Stack trace:
#0 /var/www/task.local/vendor/yiisoft/yii2/base/Module.php(528): yii\base\Controller->runAction('error', Array)
#1 /var/www/task.local/vendor/yiisoft/yii2/web/ErrorHandler.php(108): yii\base\Module->runAction('site/error')
#2 /var/www/task.local/vendor/yiisoft/yii2/base/ErrorHandler.php(111): yii\web\ErrorHandler->renderException(Object(yii\web\NotFoundHttpException))
#3 [internal function]: yii\base\ErrorHandler->handleException(Object(yii\web\NotFoundHttpException))
#4 {main}
Previous exception:
yii\base\InvalidRouteException: Unable to resolve the request "frontend/web/css/style.css". in /var/www/task.local/vendor/yiisoft/yii2/base/Module.php:537
Stack trace:
#0 /var/www/task.local/vendor/yiisoft/yii2/web/Application.php(103): yii\base\Module->runAction('frontend/web/cs...', Array)
#1 /var/w" while reading upstream, client: 127.0.0.1, server: task.local.frontend, request: "GET /frontend/web/css/style.css HTTP/1.1", upstream: "fastcgi://unix:/var/run/php/php7.2-fpm.sock:", host: "task.local.frontend", referrer: "http://task.local.frontend/login?error=%D0%92%D1%8B+%D0%BD%D0%B5%D0%B0%D0%B2%D1%82%D0%BE%D1%80%D0%B8%D0%B7%D0%B8%D1%80%D0%BE%D0%B2%D0%B0%D0%BD%D1%8B"
2019/07/05 09:17:37 [error] 983#983: *75 FastCGI sent in stderr: "PHP message: An Error occurred while handling another error:
yii\base\InvalidRouteException: Unable to resolve the request: site/error in /var/www/task.local/vendor/yiisoft/yii2/base/Controller.php:128
Stack trace:
#0 /var/www/task.local/vendor/yiisoft/yii2/base/Module.php(528): yii\base\Controller->runAction('error', Array)
#1 /var/www/task.local/vendor/yiisoft/yii2/web/ErrorHandler.php(108): yii\base\Module->runAction('site/error')
#2 /var/www/task.local/vendor/yiisoft/yii2/base/ErrorHandler.php(111): yii\web\ErrorHandler->renderException(Object(yii\web\NotFoundHttpException))
#3 [internal function]: yii\base\ErrorHandler->handleException(Object(yii\web\NotFoundHttpException))
#4 {main}
Previous exception:
yii\base\InvalidRouteException: Unable to resolve the request "cabinet/admin". in /var/www/task.local/vendor/yiisoft/yii2/base/Module.php:537
Stack trace:
#0 /var/www/task.local/vendor/yiisoft/yii2/web/Application.php(103): yii\base\Module->runAction('cabinet/admin', Array)
#1 /var/www/task.local/vend" while reading upstream, client: 127.0.0.1, server: task.local.frontend, request: "GET /cabinet/admin HTTP/1.1", upstream: "fastcgi://unix:/var/run/php/php7.2-fpm.sock:", host: "task.local.frontend", referrer: "http://task.local.frontend/login"
2019/07/05 21:18:23 [error] 955#955: *14 FastCGI sent in stderr: "PHP message: An Error occurred while handling another error:
yii\base\InvalidRouteException: Unable to resolve the request: site/error in /var/www/task.local/vendor/yiisoft/yii2/base/Controller.php:128
Stack trace:
#0 /var/www/task.local/vendor/yiisoft/yii2/base/Module.php(528): yii\base\Controller->runAction('error', Array)
#1 /var/www/task.local/vendor/yiisoft/yii2/web/ErrorHandler.php(108): yii\base\Module->runAction('site/error')
#2 /var/www/task.local/vendor/yiisoft/yii2/base/ErrorHandler.php(111): yii\web\ErrorHandler->renderException(Object(yii\web\NotFoundHttpException))
#3 [internal function]: yii\base\ErrorHandler->handleException(Object(yii\web\NotFoundHttpException))
#4 {main}
Previous exception:
yii\base\InvalidRouteException: Unable to resolve the request "frontend/web/css/style.css". in /var/www/task.local/vendor/yiisoft/yii2/base/Module.php:537
Stack trace:
#0 /var/www/task.local/vendor/yiisoft/yii2/web/Application.php(103): yii\base\Module->runAction('frontend/web/cs...', Array)
#1 /var/w" while reading upstream, client: 127.0.0.1, server: task.local.frontend, request: "GET /frontend/web/css/style.css HTTP/1.1", upstream: "fastcgi://unix:/var/run/php/php7.2-fpm.sock:", host: "task.local.frontend", referrer: "http://task.local.frontend/"
2019/07/05 21:18:23 [error] 955#955: *5 FastCGI sent in stderr: "PHP message: An Error occurred while handling another error:
yii\base\InvalidRouteException: Unable to resolve the request: site/error in /var/www/task.local/vendor/yiisoft/yii2/base/Controller.php:128
Stack trace:
#0 /var/www/task.local/vendor/yiisoft/yii2/base/Module.php(528): yii\base\Controller->runAction('error', Array)
#1 /var/www/task.local/vendor/yiisoft/yii2/web/ErrorHandler.php(108): yii\base\Module->runAction('site/error')
#2 /var/www/task.local/vendor/yiisoft/yii2/base/ErrorHandler.php(111): yii\web\ErrorHandler->renderException(Object(yii\web\NotFoundHttpException))
#3 [internal function]: yii\base\ErrorHandler->handleException(Object(yii\web\NotFoundHttpException))
#4 {main}
Previous exception:
yii\base\InvalidRouteException: Unable to resolve the request "frontend/web/css/css/all.css". in /var/www/task.local/vendor/yiisoft/yii2/base/Module.php:537
Stack trace:
#0 /var/www/task.local/vendor/yiisoft/yii2/web/Application.php(103): yii\base\Module->runAction('frontend/web/cs...', Array)
#1 /var" while reading upstream, client: 127.0.0.1, server: task.local.frontend, request: "GET /frontend/web/css/css/all.css HTTP/1.1", upstream: "fastcgi://unix:/var/run/php/php7.2-fpm.sock:", host: "task.local.frontend", referrer: "http://task.local.frontend/"
2019/07/05 21:19:01 [error] 955#955: *14 FastCGI sent in stderr: "PHP message: An Error occurred while handling another error:
yii\base\InvalidRouteException: Unable to resolve the request: site/error in /var/www/task.local/vendor/yiisoft/yii2/base/Controller.php:128
Stack trace:
#0 /var/www/task.local/vendor/yiisoft/yii2/base/Module.php(528): yii\base\Controller->runAction('error', Array)
#1 /var/www/task.local/vendor/yiisoft/yii2/web/ErrorHandler.php(108): yii\base\Module->runAction('site/error')
#2 /var/www/task.local/vendor/yiisoft/yii2/base/ErrorHandler.php(111): yii\web\ErrorHandler->renderException(Object(yii\web\NotFoundHttpException))
#3 [internal function]: yii\base\ErrorHandler->handleException(Object(yii\web\NotFoundHttpException))
#4 {main}
Previous exception:
yii\base\InvalidRouteException: Unable to resolve the request "frontend/web/css/css/all.css". in /var/www/task.local/vendor/yiisoft/yii2/base/Module.php:537
Stack trace:
#0 /var/www/task.local/vendor/yiisoft/yii2/web/Application.php(103): yii\base\Module->runAction('frontend/web/cs...', Array)
#1 /var" while reading upstream, client: 127.0.0.1, server: task.local.frontend, request: "GET /frontend/web/css/css/all.css HTTP/1.1", upstream: "fastcgi://unix:/var/run/php/php7.2-fpm.sock:", host: "task.local.frontend", referrer: "http://task.local.frontend/"
2019/07/05 21:19:01 [error] 955#955: *5 FastCGI sent in stderr: "PHP message: An Error occurred while handling another error:
yii\base\InvalidRouteException: Unable to resolve the request: site/error in /var/www/task.local/vendor/yiisoft/yii2/base/Controller.php:128
Stack trace:
#0 /var/www/task.local/vendor/yiisoft/yii2/base/Module.php(528): yii\base\Controller->runAction('error', Array)
#1 /var/www/task.local/vendor/yiisoft/yii2/web/ErrorHandler.php(108): yii\base\Module->runAction('site/error')
#2 /var/www/task.local/vendor/yiisoft/yii2/base/ErrorHandler.php(111): yii\web\ErrorHandler->renderException(Object(yii\web\NotFoundHttpException))
#3 [internal function]: yii\base\ErrorHandler->handleException(Object(yii\web\NotFoundHttpException))
#4 {main}
Previous exception:
yii\base\InvalidRouteException: Unable to resolve the request "frontend/web/css/style.css". in /var/www/task.local/vendor/yiisoft/yii2/base/Module.php:537
Stack trace:
#0 /var/www/task.local/vendor/yiisoft/yii2/web/Application.php(103): yii\base\Module->runAction('frontend/web/cs...', Array)
#1 /var/w" while reading upstream, client: 127.0.0.1, server: task.local.frontend, request: "GET /frontend/web/css/style.css HTTP/1.1", upstream: "fastcgi://unix:/var/run/php/php7.2-fpm.sock:", host: "task.local.frontend", referrer: "http://task.local.frontend/"
2019/07/05 21:19:10 [error] 955#955: *14 FastCGI sent in stderr: "PHP message: An Error occurred while handling another error:
yii\base\InvalidRouteException: Unable to resolve the request: site/error in /var/www/task.local/vendor/yiisoft/yii2/base/Controller.php:128
Stack trace:
#0 /var/www/task.local/vendor/yiisoft/yii2/base/Module.php(528): yii\base\Controller->runAction('error', Array)
#1 /var/www/task.local/vendor/yiisoft/yii2/web/ErrorHandler.php(108): yii\base\Module->runAction('site/error')
#2 /var/www/task.local/vendor/yiisoft/yii2/base/ErrorHandler.php(111): yii\web\ErrorHandler->renderException(Object(yii\web\NotFoundHttpException))
#3 [internal function]: yii\base\ErrorHandler->handleException(Object(yii\web\NotFoundHttpException))
#4 {main}
Previous exception:
yii\base\InvalidRouteException: Unable to resolve the request "frontend/web/css/css/all.css". in /var/www/task.local/vendor/yiisoft/yii2/base/Module.php:537
Stack trace:
#0 /var/www/task.local/vendor/yiisoft/yii2/web/Application.php(103): yii\base\Module->runAction('frontend/web/cs...', Array)
#1 /var" while reading upstream, client: 127.0.0.1, server: task.local.frontend, request: "GET /frontend/web/css/css/all.css HTTP/1.1", upstream: "fastcgi://unix:/var/run/php/php7.2-fpm.sock:", host: "task.local.frontend", referrer: "http://task.local.frontend/"
2019/07/05 21:19:10 [error] 955#955: *5 FastCGI sent in stderr: "PHP message: An Error occurred while handling another error:
yii\base\InvalidRouteException: Unable to resolve the request: site/error in /var/www/task.local/vendor/yiisoft/yii2/base/Controller.php:128
Stack trace:
#0 /var/www/task.local/vendor/yiisoft/yii2/base/Module.php(528): yii\base\Controller->runAction('error', Array)
#1 /var/www/task.local/vendor/yiisoft/yii2/web/ErrorHandler.php(108): yii\base\Module->runAction('site/error')
#2 /var/www/task.local/vendor/yiisoft/yii2/base/ErrorHandler.php(111): yii\web\ErrorHandler->renderException(Object(yii\web\NotFoundHttpException))
#3 [internal function]: yii\base\ErrorHandler->handleException(Object(yii\web\NotFoundHttpException))
#4 {main}
Previous exception:
yii\base\InvalidRouteException: Unable to resolve the request "frontend/web/css/style.css". in /var/www/task.local/vendor/yiisoft/yii2/base/Module.php:537
Stack trace:
#0 /var/www/task.local/vendor/yiisoft/yii2/web/Application.php(103): yii\base\Module->runAction('frontend/web/cs...', Array)
#1 /var/w" while reading upstream, client: 127.0.0.1, server: task.local.frontend, request: "GET /frontend/web/css/style.css HTTP/1.1", upstream: "fastcgi://unix:/var/run/php/php7.2-fpm.sock:", host: "task.local.frontend", referrer: "http://task.local.frontend/"
2019/07/05 21:19:19 [error] 955#955: *14 FastCGI sent in stderr: "PHP message: An Error occurred while handling another error:
yii\base\InvalidRouteException: Unable to resolve the request: site/error in /var/www/task.local/vendor/yiisoft/yii2/base/Controller.php:128
Stack trace:
#0 /var/www/task.local/vendor/yiisoft/yii2/base/Module.php(528): yii\base\Controller->runAction('error', Array)
#1 /var/www/task.local/vendor/yiisoft/yii2/web/ErrorHandler.php(108): yii\base\Module->runAction('site/error')
#2 /var/www/task.local/vendor/yiisoft/yii2/base/ErrorHandler.php(111): yii\web\ErrorHandler->renderException(Object(yii\web\NotFoundHttpException))
#3 [internal function]: yii\base\ErrorHandler->handleException(Object(yii\web\NotFoundHttpException))
#4 {main}
Previous exception:
yii\base\InvalidRouteException: Unable to resolve the request "frontend/web/css/css/all.css". in /var/www/task.local/vendor/yiisoft/yii2/base/Module.php:537
Stack trace:
#0 /var/www/task.local/vendor/yiisoft/yii2/web/Application.php(103): yii\base\Module->runAction('frontend/web/cs...', Array)
#1 /var" while reading upstream, client: 127.0.0.1, server: task.local.frontend, request: "GET /frontend/web/css/css/all.css HTTP/1.1", upstream: "fastcgi://unix:/var/run/php/php7.2-fpm.sock:", host: "task.local.frontend", referrer: "http://task.local.frontend/"
2019/07/05 21:19:19 [error] 955#955: *5 FastCGI sent in stderr: "PHP message: An Error occurred while handling another error:
yii\base\InvalidRouteException: Unable to resolve the request: site/error in /var/www/task.local/vendor/yiisoft/yii2/base/Controller.php:128
Stack trace:
#0 /var/www/task.local/vendor/yiisoft/yii2/base/Module.php(528): yii\base\Controller->runAction('error', Array)
#1 /var/www/task.local/vendor/yiisoft/yii2/web/ErrorHandler.php(108): yii\base\Module->runAction('site/error')
#2 /var/www/task.local/vendor/yiisoft/yii2/base/ErrorHandler.php(111): yii\web\ErrorHandler->renderException(Object(yii\web\NotFoundHttpException))
#3 [internal function]: yii\base\ErrorHandler->handleException(Object(yii\web\NotFoundHttpException))
#4 {main}
Previous exception:
yii\base\InvalidRouteException: Unable to resolve the request "frontend/web/css/style.css". in /var/www/task.local/vendor/yiisoft/yii2/base/Module.php:537
Stack trace:
#0 /var/www/task.local/vendor/yiisoft/yii2/web/Application.php(103): yii\base\Module->runAction('frontend/web/cs...', Array)
#1 /var/w" while reading upstream, client: 127.0.0.1, server: task.local.frontend, request: "GET /frontend/web/css/style.css HTTP/1.1", upstream: "fastcgi://unix:/var/run/php/php7.2-fpm.sock:", host: "task.local.frontend", referrer: "http://task.local.frontend/"
2019/07/05 21:19:26 [error] 955#955: *5 FastCGI sent in stderr: "PHP message: An Error occurred while handling another error:
yii\base\InvalidRouteException: Unable to resolve the request: site/error in /var/www/task.local/vendor/yiisoft/yii2/base/Controller.php:128
Stack trace:
#0 /var/www/task.local/vendor/yiisoft/yii2/base/Module.php(528): yii\base\Controller->runAction('error', Array)
#1 /var/www/task.local/vendor/yiisoft/yii2/web/ErrorHandler.php(108): yii\base\Module->runAction('site/error')
#2 /var/www/task.local/vendor/yiisoft/yii2/base/ErrorHandler.php(111): yii\web\ErrorHandler->renderException(Object(yii\web\NotFoundHttpException))
#3 [internal function]: yii\base\ErrorHandler->handleException(Object(yii\web\NotFoundHttpException))
#4 {main}
Previous exception:
yii\base\InvalidRouteException: Unable to resolve the request "auth". in /var/www/task.local/vendor/yiisoft/yii2/base/Module.php:537
Stack trace:
#0 /var/www/task.local/vendor/yiisoft/yii2/web/Application.php(103): yii\base\Module->runAction('auth', Array)
#1 /var/www/task.local/vendor/yiisoft/yii2/ba" while reading upstream, client: 127.0.0.1, server: task.local.frontend, request: "GET /auth HTTP/1.1", upstream: "fastcgi://unix:/var/run/php/php7.2-fpm.sock:", host: "task.local.frontend"
2019/07/05 21:20:51 [error] 955#955: *46 FastCGI sent in stderr: "PHP message: An Error occurred while handling another error:
yii\base\InvalidRouteException: Unable to resolve the request: site/error in /var/www/task.local/vendor/yiisoft/yii2/base/Controller.php:128
Stack trace:
#0 /var/www/task.local/vendor/yiisoft/yii2/base/Module.php(528): yii\base\Controller->runAction('error', Array)
#1 /var/www/task.local/vendor/yiisoft/yii2/web/ErrorHandler.php(108): yii\base\Module->runAction('site/error')
#2 /var/www/task.local/vendor/yiisoft/yii2/base/ErrorHandler.php(111): yii\web\ErrorHandler->renderException(Object(yii\web\NotFoundHttpException))
#3 [internal function]: yii\base\ErrorHandler->handleException(Object(yii\web\NotFoundHttpException))
#4 {main}
Previous exception:
yii\base\InvalidRouteException: Unable to resolve the request "frontend/web/css/css/all.css". in /var/www/task.local/vendor/yiisoft/yii2/base/Module.php:537
Stack trace:
#0 /var/www/task.local/vendor/yiisoft/yii2/web/Application.php(103): yii\base\Module->runAction('frontend/web/cs...', Array)
#1 /var" while reading upstream, client: 127.0.0.1, server: task.local.frontend, request: "GET /frontend/web/css/css/all.css HTTP/1.1", upstream: "fastcgi://unix:/var/run/php/php7.2-fpm.sock:", host: "task.local.frontend", referrer: "http://task.local.frontend/"
2019/07/05 21:20:51 [error] 955#955: *50 FastCGI sent in stderr: "PHP message: An Error occurred while handling another error:
yii\base\InvalidRouteException: Unable to resolve the request: site/error in /var/www/task.local/vendor/yiisoft/yii2/base/Controller.php:128
Stack trace:
#0 /var/www/task.local/vendor/yiisoft/yii2/base/Module.php(528): yii\base\Controller->runAction('error', Array)
#1 /var/www/task.local/vendor/yiisoft/yii2/web/ErrorHandler.php(108): yii\base\Module->runAction('site/error')
#2 /var/www/task.local/vendor/yiisoft/yii2/base/ErrorHandler.php(111): yii\web\ErrorHandler->renderException(Object(yii\web\NotFoundHttpException))
#3 [internal function]: yii\base\ErrorHandler->handleException(Object(yii\web\NotFoundHttpException))
#4 {main}
Previous exception:
yii\base\InvalidRouteException: Unable to resolve the request "frontend/web/css/style.css". in /var/www/task.local/vendor/yiisoft/yii2/base/Module.php:537
Stack trace:
#0 /var/www/task.local/vendor/yiisoft/yii2/web/Application.php(103): yii\base\Module->runAction('frontend/web/cs...', Array)
#1 /var/w" while reading upstream, client: 127.0.0.1, server: task.local.frontend, request: "GET /frontend/web/css/style.css HTTP/1.1", upstream: "fastcgi://unix:/var/run/php/php7.2-fpm.sock:", host: "task.local.frontend", referrer: "http://task.local.frontend/"
2019/07/05 21:21:07 [error] 955#955: *50 FastCGI sent in stderr: "PHP message: An Error occurred while handling another error:
yii\base\InvalidRouteException: Unable to resolve the request: site/error in /var/www/task.local/vendor/yiisoft/yii2/base/Controller.php:128
Stack trace:
#0 /var/www/task.local/vendor/yiisoft/yii2/base/Module.php(528): yii\base\Controller->runAction('error', Array)
#1 /var/www/task.local/vendor/yiisoft/yii2/web/ErrorHandler.php(108): yii\base\Module->runAction('site/error')
#2 /var/www/task.local/vendor/yiisoft/yii2/base/ErrorHandler.php(111): yii\web\ErrorHandler->renderException(Object(yii\web\NotFoundHttpException))
#3 [internal function]: yii\base\ErrorHandler->handleException(Object(yii\web\NotFoundHttpException))
#4 {main}
Previous exception:
yii\base\InvalidRouteException: Unable to resolve the request "frontend/web/css/css/all.css". in /var/www/task.local/vendor/yiisoft/yii2/base/Module.php:537
Stack trace:
#0 /var/www/task.local/vendor/yiisoft/yii2/web/Application.php(103): yii\base\Module->runAction('frontend/web/cs...', Array)
#1 /var" while reading upstream, client: 127.0.0.1, server: task.local.frontend, request: "GET /frontend/web/css/css/all.css HTTP/1.1", upstream: "fastcgi://unix:/var/run/php/php7.2-fpm.sock:", host: "task.local.frontend", referrer: "http://task.local.frontend/"
2019/07/05 21:21:07 [error] 955#955: *46 FastCGI sent in stderr: "PHP message: An Error occurred while handling another error:
yii\base\InvalidRouteException: Unable to resolve the request: site/error in /var/www/task.local/vendor/yiisoft/yii2/base/Controller.php:128
Stack trace:
#0 /var/www/task.local/vendor/yiisoft/yii2/base/Module.php(528): yii\base\Controller->runAction('error', Array)
#1 /var/www/task.local/vendor/yiisoft/yii2/web/ErrorHandler.php(108): yii\base\Module->runAction('site/error')
#2 /var/www/task.local/vendor/yiisoft/yii2/base/ErrorHandler.php(111): yii\web\ErrorHandler->renderException(Object(yii\web\NotFoundHttpException))
#3 [internal function]: yii\base\ErrorHandler->handleException(Object(yii\web\NotFoundHttpException))
#4 {main}
Previous exception:
yii\base\InvalidRouteException: Unable to resolve the request "frontend/web/css/style.css". in /var/www/task.local/vendor/yiisoft/yii2/base/Module.php:537
Stack trace:
#0 /var/www/task.local/vendor/yiisoft/yii2/web/Application.php(103): yii\base\Module->runAction('frontend/web/cs...', Array)
#1 /var/w" while reading upstream, client: 127.0.0.1, server: task.local.frontend, request: "GET /frontend/web/css/style.css HTTP/1.1", upstream: "fastcgi://unix:/var/run/php/php7.2-fpm.sock:", host: "task.local.frontend", referrer: "http://task.local.frontend/"
2019/07/05 21:22:59 [error] 955#955: *61 FastCGI sent in stderr: "PHP message: An Error occurred while handling another error:
yii\base\InvalidRouteException: Unable to resolve the request: site/error in /var/www/task.local/vendor/yiisoft/yii2/base/Controller.php:128
Stack trace:
#0 /var/www/task.local/vendor/yiisoft/yii2/base/Module.php(528): yii\base\Controller->runAction('error', Array)
#1 /var/www/task.local/vendor/yiisoft/yii2/web/ErrorHandler.php(108): yii\base\Module->runAction('site/error')
#2 /var/www/task.local/vendor/yiisoft/yii2/base/ErrorHandler.php(111): yii\web\ErrorHandler->renderException(Object(yii\web\NotFoundHttpException))
#3 [internal function]: yii\base\ErrorHandler->handleException(Object(yii\web\NotFoundHttpException))
#4 {main}
Previous exception:
yii\base\InvalidRouteException: Unable to resolve the request "frontend/web/css/css/all.css". in /var/www/task.local/vendor/yiisoft/yii2/base/Module.php:537
Stack trace:
#0 /var/www/task.local/vendor/yiisoft/yii2/web/Application.php(103): yii\base\Module->runAction('frontend/web/cs...', Array)
#1 /var" while reading upstream, client: 127.0.0.1, server: task.local.frontend, request: "GET /frontend/web/css/css/all.css HTTP/1.1", upstream: "fastcgi://unix:/var/run/php/php7.2-fpm.sock:", host: "task.local.frontend", referrer: "http://task.local.frontend/"
2019/07/05 21:22:59 [error] 955#955: *65 FastCGI sent in stderr: "PHP message: An Error occurred while handling another error:
yii\base\InvalidRouteException: Unable to resolve the request: site/error in /var/www/task.local/vendor/yiisoft/yii2/base/Controller.php:128
Stack trace:
#0 /var/www/task.local/vendor/yiisoft/yii2/base/Module.php(528): yii\base\Controller->runAction('error', Array)
#1 /var/www/task.local/vendor/yiisoft/yii2/web/ErrorHandler.php(108): yii\base\Module->runAction('site/error')
#2 /var/www/task.local/vendor/yiisoft/yii2/base/ErrorHandler.php(111): yii\web\ErrorHandler->renderException(Object(yii\web\NotFoundHttpException))
#3 [internal function]: yii\base\ErrorHandler->handleException(Object(yii\web\NotFoundHttpException))
#4 {main}
Previous exception:
yii\base\InvalidRouteException: Unable to resolve the request "frontend/web/css/style.css". in /var/www/task.local/vendor/yiisoft/yii2/base/Module.php:537
Stack trace:
#0 /var/www/task.local/vendor/yiisoft/yii2/web/Application.php(103): yii\base\Module->runAction('frontend/web/cs...', Array)
#1 /var/w" while reading upstream, client: 127.0.0.1, server: task.local.frontend, request: "GET /frontend/web/css/style.css HTTP/1.1", upstream: "fastcgi://unix:/var/run/php/php7.2-fpm.sock:", host: "task.local.frontend", referrer: "http://task.local.frontend/"
2019/07/05 21:24:05 [error] 955#955: *61 FastCGI sent in stderr: "PHP message: An Error occurred while handling another error:
yii\base\InvalidRouteException: Unable to resolve the request: site/error in /var/www/task.local/vendor/yiisoft/yii2/base/Controller.php:128
Stack trace:
#0 /var/www/task.local/vendor/yiisoft/yii2/base/Module.php(528): yii\base\Controller->runAction('error', Array)
#1 /var/www/task.local/vendor/yiisoft/yii2/web/ErrorHandler.php(108): yii\base\Module->runAction('site/error')
#2 /var/www/task.local/vendor/yiisoft/yii2/base/ErrorHandler.php(111): yii\web\ErrorHandler->renderException(Object(yii\web\NotFoundHttpException))
#3 [internal function]: yii\base\ErrorHandler->handleException(Object(yii\web\NotFoundHttpException))
#4 {main}
Previous exception:
yii\base\InvalidRouteException: Unable to resolve the request "frontend/web/css/css/all.css". in /var/www/task.local/vendor/yiisoft/yii2/base/Module.php:537
Stack trace:
#0 /var/www/task.local/vendor/yiisoft/yii2/web/Application.php(103): yii\base\Module->runAction('frontend/web/cs...', Array)
#1 /var" while reading upstream, client: 127.0.0.1, server: task.local.frontend, request: "GET /frontend/web/css/css/all.css HTTP/1.1", upstream: "fastcgi://unix:/var/run/php/php7.2-fpm.sock:", host: "task.local.frontend", referrer: "http://task.local.frontend/"
2019/07/05 21:24:05 [error] 955#955: *73 FastCGI sent in stderr: "PHP message: An Error occurred while handling another error:
yii\base\InvalidRouteException: Unable to resolve the request: site/error in /var/www/task.local/vendor/yiisoft/yii2/base/Controller.php:128
Stack trace:
#0 /var/www/task.local/vendor/yiisoft/yii2/base/Module.php(528): yii\base\Controller->runAction('error', Array)
#1 /var/www/task.local/vendor/yiisoft/yii2/web/ErrorHandler.php(108): yii\base\Module->runAction('site/error')
#2 /var/www/task.local/vendor/yiisoft/yii2/base/ErrorHandler.php(111): yii\web\ErrorHandler->renderException(Object(yii\web\NotFoundHttpException))
#3 [internal function]: yii\base\ErrorHandler->handleException(Object(yii\web\NotFoundHttpException))
#4 {main}
Previous exception:
yii\base\InvalidRouteException: Unable to resolve the request "frontend/web/css/style.css". in /var/www/task.local/vendor/yiisoft/yii2/base/Module.php:537
Stack trace:
#0 /var/www/task.local/vendor/yiisoft/yii2/web/Application.php(103): yii\base\Module->runAction('frontend/web/cs...', Array)
#1 /var/w" while reading upstream, client: 127.0.0.1, server: task.local.frontend, request: "GET /frontend/web/css/style.css HTTP/1.1", upstream: "fastcgi://unix:/var/run/php/php7.2-fpm.sock:", host: "task.local.frontend", referrer: "http://task.local.frontend/"
2019/07/05 21:34:54 [error] 955#955: *79 FastCGI sent in stderr: "PHP message: An Error occurred while handling another error:
yii\base\InvalidRouteException: Unable to resolve the request: site/error in /var/www/task.local/vendor/yiisoft/yii2/base/Controller.php:128
Stack trace:
#0 /var/www/task.local/vendor/yiisoft/yii2/base/Module.php(528): yii\base\Controller->runAction('error', Array)
#1 /var/www/task.local/vendor/yiisoft/yii2/web/ErrorHandler.php(108): yii\base\Module->runAction('site/error')
#2 /var/www/task.local/vendor/yiisoft/yii2/base/ErrorHandler.php(111): yii\web\ErrorHandler->renderException(Object(yii\web\NotFoundHttpException))
#3 [internal function]: yii\base\ErrorHandler->handleException(Object(yii\web\NotFoundHttpException))
#4 {main}
Previous exception:
yii\base\InvalidRouteException: Unable to resolve the request "frontend/web/css/css/all.css". in /var/www/task.local/vendor/yiisoft/yii2/base/Module.php:537
Stack trace:
#0 /var/www/task.local/vendor/yiisoft/yii2/web/Application.php(103): yii\base\Module->runAction('frontend/web/cs...', Array)
#1 /var" while reading upstream, client: 127.0.0.1, server: task.local.frontend, request: "GET /frontend/web/css/css/all.css HTTP/1.1", upstream: "fastcgi://unix:/var/run/php/php7.2-fpm.sock:", host: "task.local.frontend", referrer: "http://task.local.frontend/"
2019/07/05 21:34:54 [error] 955#955: *82 FastCGI sent in stderr: "PHP message: An Error occurred while handling another error:
yii\base\InvalidRouteException: Unable to resolve the request: site/error in /var/www/task.local/vendor/yiisoft/yii2/base/Controller.php:128
Stack trace:
#0 /var/www/task.local/vendor/yiisoft/yii2/base/Module.php(528): yii\base\Controller->runAction('error', Array)
#1 /var/www/task.local/vendor/yiisoft/yii2/web/ErrorHandler.php(108): yii\base\Module->runAction('site/error')
#2 /var/www/task.local/vendor/yiisoft/yii2/base/ErrorHandler.php(111): yii\web\ErrorHandler->renderException(Object(yii\web\NotFoundHttpException))
#3 [internal function]: yii\base\ErrorHandler->handleException(Object(yii\web\NotFoundHttpException))
#4 {main}
Previous exception:
yii\base\InvalidRouteException: Unable to resolve the request "frontend/web/css/style.css". in /var/www/task.local/vendor/yiisoft/yii2/base/Module.php:537
Stack trace:
#0 /var/www/task.local/vendor/yiisoft/yii2/web/Application.php(103): yii\base\Module->runAction('frontend/web/cs...', Array)
#1 /var/w" while reading upstream, client: 127.0.0.1, server: task.local.frontend, request: "GET /frontend/web/css/style.css HTTP/1.1", upstream: "fastcgi://unix:/var/run/php/php7.2-fpm.sock:", host: "task.local.frontend", referrer: "http://task.local.frontend/"
2019/07/05 21:45:36 [error] 955#955: *87 FastCGI sent in stderr: "PHP message: An Error occurred while handling another error:
yii\base\InvalidRouteException: Unable to resolve the request: site/error in /var/www/task.local/vendor/yiisoft/yii2/base/Controller.php:128
Stack trace:
#0 /var/www/task.local/vendor/yiisoft/yii2/base/Module.php(528): yii\base\Controller->runAction('error', Array)
#1 /var/www/task.local/vendor/yiisoft/yii2/web/ErrorHandler.php(108): yii\base\Module->runAction('site/error')
#2 /var/www/task.local/vendor/yiisoft/yii2/base/ErrorHandler.php(111): yii\web\ErrorHandler->renderException(Object(yii\web\NotFoundHttpException))
#3 [internal function]: yii\base\ErrorHandler->handleException(Object(yii\web\NotFoundHttpException))
#4 {main}
Previous exception:
yii\base\InvalidRouteException: Unable to resolve the request "frontend/web/css/style.css". in /var/www/task.local/vendor/yiisoft/yii2/base/Module.php:537
Stack trace:
#0 /var/www/task.local/vendor/yiisoft/yii2/web/Application.php(103): yii\base\Module->runAction('frontend/web/cs...', Array)
#1 /var/w" while reading upstream, client: 127.0.0.1, server: task.local.frontend, request: "GET /frontend/web/css/style.css HTTP/1.1", upstream: "fastcgi://unix:/var/run/php/php7.2-fpm.sock:", host: "task.local.frontend", referrer: "http://task.local.frontend/"
2019/07/05 21:45:36 [error] 955#955: *90 FastCGI sent in stderr: "PHP message: An Error occurred while handling another error:
yii\base\InvalidRouteException: Unable to resolve the request: site/error in /var/www/task.local/vendor/yiisoft/yii2/base/Controller.php:128
Stack trace:
#0 /var/www/task.local/vendor/yiisoft/yii2/base/Module.php(528): yii\base\Controller->runAction('error', Array)
#1 /var/www/task.local/vendor/yiisoft/yii2/web/ErrorHandler.php(108): yii\base\Module->runAction('site/error')
#2 /var/www/task.local/vendor/yiisoft/yii2/base/ErrorHandler.php(111): yii\web\ErrorHandler->renderException(Object(yii\web\NotFoundHttpException))
#3 [internal function]: yii\base\ErrorHandler->handleException(Object(yii\web\NotFoundHttpException))
#4 {main}
Previous exception:
yii\base\InvalidRouteException: Unable to resolve the request "frontend/web/css/css/all.css". in /var/www/task.local/vendor/yiisoft/yii2/base/Module.php:537
Stack trace:
#0 /var/www/task.local/vendor/yiisoft/yii2/web/Application.php(103): yii\base\Module->runAction('frontend/web/cs...', Array)
#1 /var" while reading upstream, client: 127.0.0.1, server: task.local.frontend, request: "GET /frontend/web/css/css/all.css HTTP/1.1", upstream: "fastcgi://unix:/var/run/php/php7.2-fpm.sock:", host: "task.local.frontend", referrer: "http://task.local.frontend/"
2019/07/05 21:50:35 [error] 956#956: *94 FastCGI sent in stderr: "PHP message: An Error occurred while handling another error:
yii\base\InvalidRouteException: Unable to resolve the request: site/error in /var/www/task.local/vendor/yiisoft/yii2/base/Controller.php:128
Stack trace:
#0 /var/www/task.local/vendor/yiisoft/yii2/base/Module.php(528): yii\base\Controller->runAction('error', Array)
#1 /var/www/task.local/vendor/yiisoft/yii2/web/ErrorHandler.php(108): yii\base\Module->runAction('site/error')
#2 /var/www/task.local/vendor/yiisoft/yii2/base/ErrorHandler.php(111): yii\web\ErrorHandler->renderException(Object(yii\web\NotFoundHttpException))
#3 [internal function]: yii\base\ErrorHandler->handleException(Object(yii\web\NotFoundHttpException))
#4 {main}
Previous exception:
yii\base\InvalidRouteException: Unable to resolve the request: site/about in /var/www/task.local/vendor/yiisoft/yii2/base/Controller.php:128
Stack trace:
#0 /var/www/task.local/vendor/yiisoft/yii2/base/Module.php(528): yii\base\Controller->runAction('about', Array)
#1 /var/www/task.local/vendor/yiisof" while reading upstream, client: 127.0.0.1, server: task.local.frontend, request: "GET /site/about HTTP/1.1", upstream: "fastcgi://unix:/var/run/php/php7.2-fpm.sock:", host: "task.local.frontend", referrer: "http://task.local.frontend/"
2019/07/05 21:50:39 [error] 956#956: *94 FastCGI sent in stderr: "PHP message: An Error occurred while handling another error:
yii\base\InvalidRouteException: Unable to resolve the request: site/error in /var/www/task.local/vendor/yiisoft/yii2/base/Controller.php:128
Stack trace:
#0 /var/www/task.local/vendor/yiisoft/yii2/base/Module.php(528): yii\base\Controller->runAction('error', Array)
#1 /var/www/task.local/vendor/yiisoft/yii2/web/ErrorHandler.php(108): yii\base\Module->runAction('site/error')
#2 /var/www/task.local/vendor/yiisoft/yii2/base/ErrorHandler.php(111): yii\web\ErrorHandler->renderException(Object(yii\web\NotFoundHttpException))
#3 [internal function]: yii\base\ErrorHandler->handleException(Object(yii\web\NotFoundHttpException))
#4 {main}
Previous exception:
yii\base\InvalidRouteException: Unable to resolve the request: site/contact in /var/www/task.local/vendor/yiisoft/yii2/base/Controller.php:128
Stack trace:
#0 /var/www/task.local/vendor/yiisoft/yii2/base/Module.php(528): yii\base\Controller->runAction('contact', Array)
#1 /var/www/task.local/vendor/yi" while reading upstream, client: 127.0.0.1, server: task.local.frontend, request: "GET /site/contact HTTP/1.1", upstream: "fastcgi://unix:/var/run/php/php7.2-fpm.sock:", host: "task.local.frontend", referrer: "http://task.local.frontend/"
2019/07/05 23:55:40 [error] 955#955: *126 FastCGI sent in stderr: "PHP message: An Error occurred while handling another error:
yii\base\InvalidRouteException: Unable to resolve the request: site/error in /var/www/task.local/vendor/yiisoft/yii2/base/Controller.php:128
Stack trace:
#0 /var/www/task.local/vendor/yiisoft/yii2/base/Module.php(528): yii\base\Controller->runAction('error', Array)
#1 /var/www/task.local/vendor/yiisoft/yii2/web/ErrorHandler.php(108): yii\base\Module->runAction('site/error')
#2 /var/www/task.local/vendor/yiisoft/yii2/base/ErrorHandler.php(111): yii\web\ErrorHandler->renderException(Object(yii\web\NotFoundHttpException))
#3 [internal function]: yii\base\ErrorHandler->handleException(Object(yii\web\NotFoundHttpException))
#4 {main}
Previous exception:
yii\base\InvalidRouteException: Unable to resolve the request "cabinet/task/". in /var/www/task.local/vendor/yiisoft/yii2/base/Module.php:537
Stack trace:
#0 /var/www/task.local/vendor/yiisoft/yii2/web/Application.php(103): yii\base\Module->runAction('cabinet/task/', Array)
#1 /var/www/task.local/vend" while reading upstream, client: 127.0.0.1, server: task.local.frontend, request: "GET /cabinet/task/ HTTP/1.1", upstream: "fastcgi://unix:/var/run/php/php7.2-fpm.sock:", host: "task.local.frontend", referrer: "http://task.local.frontend/"
2019/07/06 00:06:04 [error] 955#955: *147 FastCGI sent in stderr: "PHP message: An Error occurred while handling another error:
yii\base\InvalidRouteException: Unable to resolve the request: site/error in /var/www/task.local/vendor/yiisoft/yii2/base/Controller.php:128
Stack trace:
#0 /var/www/task.local/vendor/yiisoft/yii2/base/Module.php(528): yii\base\Controller->runAction('error', Array)
#1 /var/www/task.local/vendor/yiisoft/yii2/web/ErrorHandler.php(108): yii\base\Module->runAction('site/error')
#2 /var/www/task.local/vendor/yiisoft/yii2/base/ErrorHandler.php(111): yii\web\ErrorHandler->renderException(Object(yii\web\NotFoundHttpException))
#3 [internal function]: yii\base\ErrorHandler->handleException(Object(yii\web\NotFoundHttpException))
#4 {main}
Previous exception:
yii\base\InvalidRouteException: Unable to resolve the request "task/index/up". in /var/www/task.local/vendor/yiisoft/yii2/base/Module.php:537
Stack trace:
#0 /var/www/task.local/vendor/yiisoft/yii2/web/Application.php(103): yii\base\Module->runAction('task/index/up', Array)
#1 /var/www/task.local/vend" while reading upstream, client: 127.0.0.1, server: task.local.frontend, request: "GET /task/index/up HTTP/1.1", upstream: "fastcgi://unix:/var/run/php/php7.2-fpm.sock:", host: "task.local.frontend", referrer: "http://task.local.frontend/task"
2019/07/06 00:06:08 [error] 955#955: *147 FastCGI sent in stderr: "PHP message: An Error occurred while handling another error:
yii\base\InvalidRouteException: Unable to resolve the request: site/error in /var/www/task.local/vendor/yiisoft/yii2/base/Controller.php:128
Stack trace:
#0 /var/www/task.local/vendor/yiisoft/yii2/base/Module.php(528): yii\base\Controller->runAction('error', Array)
#1 /var/www/task.local/vendor/yiisoft/yii2/web/ErrorHandler.php(108): yii\base\Module->runAction('site/error')
#2 /var/www/task.local/vendor/yiisoft/yii2/base/ErrorHandler.php(111): yii\web\ErrorHandler->renderException(Object(yii\web\NotFoundHttpException))
#3 [internal function]: yii\base\ErrorHandler->handleException(Object(yii\web\NotFoundHttpException))
#4 {main}
Previous exception:
yii\base\InvalidRouteException: Unable to resolve the request "task/index/down". in /var/www/task.local/vendor/yiisoft/yii2/base/Module.php:537
Stack trace:
#0 /var/www/task.local/vendor/yiisoft/yii2/web/Application.php(103): yii\base\Module->runAction('task/index/down', Array)
#1 /var/www/task.local/" while reading upstream, client: 127.0.0.1, server: task.local.frontend, request: "GET /task/index/down HTTP/1.1", upstream: "fastcgi://unix:/var/run/php/php7.2-fpm.sock:", host: "task.local.frontend", referrer: "http://task.local.frontend/task"
2019/07/06 00:07:03 [error] 955#955: *147 FastCGI sent in stderr: "PHP message: An Error occurred while handling another error:
yii\web\HeadersAlreadySentException: Headers already sent in /var/www/task.local/frontend/controllers/TaskController.php on line 19. in /var/www/task.local/vendor/yiisoft/yii2/web/Response.php:366
Stack trace:
#0 /var/www/task.local/vendor/yiisoft/yii2/web/Response.php(339): yii\web\Response->sendHeaders()
#1 /var/www/task.local/vendor/yiisoft/yii2/web/ErrorHandler.php(135): yii\web\Response->send()
#2 /var/www/task.local/vendor/yiisoft/yii2/base/ErrorHandler.php(111): yii\web\ErrorHandler->renderException(Object(yii\base\ErrorException))
#3 [internal function]: yii\base\ErrorHandler->handleException(Object(yii\base\ErrorException))
#4 {main}
Previous exception:
yii\base\ErrorException: session_set_cookie_params(): Cannot change session cookie parameters when headers already sent in /var/www/task.local/vendor/yiisoft/yii2/web/Session.php:404
Stack trace:
#0 [internal function]: yii\base\ErrorHandler->handleError(2, 'session_set_coo...', '/var/ww" while reading upstream, client: 127.0.0.1, server: task.local.frontend, request: "GET /task HTTP/1.1", upstream: "fastcgi://unix:/var/run/php/php7.2-fpm.sock:", host: "task.local.frontend", referrer: "http://task.local.frontend/"
2019/07/06 00:15:23 [error] 6926#6926: *1 FastCGI sent in stderr: "PHP message: An Error occurred while handling another error:
yii\web\HeadersAlreadySentException: Headers already sent in /var/www/task.local/frontend/controllers/TaskController.php on line 19. in /var/www/task.local/vendor/yiisoft/yii2/web/Response.php:366
Stack trace:
#0 /var/www/task.local/vendor/yiisoft/yii2/web/Response.php(339): yii\web\Response->sendHeaders()
#1 /var/www/task.local/vendor/yiisoft/yii2/web/ErrorHandler.php(135): yii\web\Response->send()
#2 /var/www/task.local/vendor/yiisoft/yii2/base/ErrorHandler.php(111): yii\web\ErrorHandler->renderException(Object(yii\base\ErrorException))
#3 [internal function]: yii\base\ErrorHandler->handleException(Object(yii\base\ErrorException))
#4 {main}
Previous exception:
yii\base\ErrorException: session_set_cookie_params(): Cannot change session cookie parameters when headers already sent in /var/www/task.local/vendor/yiisoft/yii2/web/Session.php:404
Stack trace:
#0 [internal function]: yii\base\ErrorHandler->handleError(2, 'session_set_coo...', '/var/ww" while reading upstream, client: 127.0.0.1, server: task.local.frontend, request: "GET /task HTTP/1.1", upstream: "fastcgi://unix:/var/run/php/php7.2-fpm.sock:", host: "task.local.frontend", referrer: "http://task.local.frontend/"
2019/07/06 00:15:28 [error] 6926#6926: *3 FastCGI sent in stderr: "PHP message: An Error occurred while handling another error:
yii\web\HeadersAlreadySentException: Headers already sent in /var/www/task.local/frontend/controllers/TaskController.php on line 19. in /var/www/task.local/vendor/yiisoft/yii2/web/Response.php:366
Stack trace:
#0 /var/www/task.local/vendor/yiisoft/yii2/web/Response.php(339): yii\web\Response->sendHeaders()
#1 /var/www/task.local/vendor/yiisoft/yii2/web/ErrorHandler.php(135): yii\web\Response->send()
#2 /var/www/task.local/vendor/yiisoft/yii2/base/ErrorHandler.php(111): yii\web\ErrorHandler->renderException(Object(yii\base\ErrorException))
#3 [internal function]: yii\base\ErrorHandler->handleException(Object(yii\base\ErrorException))
#4 {main}
Previous exception:
yii\base\ErrorException: session_set_cookie_params(): Cannot change session cookie parameters when headers already sent in /var/www/task.local/vendor/yiisoft/yii2/web/Session.php:404
Stack trace:
#0 [internal function]: yii\base\ErrorHandler->handleError(2, 'session_set_coo...', '/var/ww" while reading upstream, client: 127.0.0.1, server: task.local.frontend, request: "GET /task HTTP/1.1", upstream: "fastcgi://unix:/var/run/php/php7.2-fpm.sock:", host: "task.local.frontend", referrer: "http://task.local.frontend/"
2019/07/06 00:15:53 [error] 6992#6992: *1 FastCGI sent in stderr: "PHP message: An Error occurred while handling another error:
yii\web\HeadersAlreadySentException: Headers already sent in /var/www/task.local/frontend/controllers/TaskController.php on line 19. in /var/www/task.local/vendor/yiisoft/yii2/web/Response.php:366
Stack trace:
#0 /var/www/task.local/vendor/yiisoft/yii2/web/Response.php(339): yii\web\Response->sendHeaders()
#1 /var/www/task.local/vendor/yiisoft/yii2/web/ErrorHandler.php(135): yii\web\Response->send()
#2 /var/www/task.local/vendor/yiisoft/yii2/base/ErrorHandler.php(111): yii\web\ErrorHandler->renderException(Object(yii\base\ErrorException))
#3 [internal function]: yii\base\ErrorHandler->handleException(Object(yii\base\ErrorException))
#4 {main}
Previous exception:
yii\base\ErrorException: session_set_cookie_params(): Cannot change session cookie parameters when headers already sent in /var/www/task.local/vendor/yiisoft/yii2/web/Session.php:404
Stack trace:
#0 [internal function]: yii\base\ErrorHandler->handleError(2, 'session_set_coo...', '/var/ww" while reading upstream, client: 127.0.0.1, server: task.local.frontend, request: "GET /task HTTP/1.1", upstream: "fastcgi://unix:/var/run/php/php7.2-fpm.sock:", host: "task.local.frontend", referrer: "http://task.local.frontend/"
2019/07/06 00:17:16 [error] 7039#7039: *1 FastCGI sent in stderr: "PHP message: An Error occurred while handling another error:
yii\web\HeadersAlreadySentException: Headers already sent in /var/www/task.local/frontend/controllers/TaskController.php on line 19. in /var/www/task.local/vendor/yiisoft/yii2/web/Response.php:366
Stack trace:
#0 /var/www/task.local/vendor/yiisoft/yii2/web/Response.php(339): yii\web\Response->sendHeaders()
#1 /var/www/task.local/vendor/yiisoft/yii2/web/ErrorHandler.php(135): yii\web\Response->send()
#2 /var/www/task.local/vendor/yiisoft/yii2/base/ErrorHandler.php(111): yii\web\ErrorHandler->renderException(Object(yii\base\ErrorException))
#3 [internal function]: yii\base\ErrorHandler->handleException(Object(yii\base\ErrorException))
#4 {main}
Previous exception:
yii\base\ErrorException: session_set_cookie_params(): Cannot change session cookie parameters when headers already sent in /var/www/task.local/vendor/yiisoft/yii2/web/Session.php:404
Stack trace:
#0 [internal function]: yii\base\ErrorHandler->handleError(2, 'session_set_coo...', '/var/ww" while reading upstream, client: 127.0.0.1, server: task.local.frontend, request: "GET /task HTTP/1.1", upstream: "fastcgi://unix:/var/run/php/php7.2-fpm.sock:", host: "task.local.frontend", referrer: "http://task.local.frontend/"
2019/07/06 00:17:22 [error] 7039#7039: *1 FastCGI sent in stderr: "PHP message: An Error occurred while handling another error:
yii\web\HeadersAlreadySentException: Headers already sent in /var/www/task.local/frontend/controllers/TaskController.php on line 19. in /var/www/task.local/vendor/yiisoft/yii2/web/Response.php:366
Stack trace:
#0 /var/www/task.local/vendor/yiisoft/yii2/web/Response.php(339): yii\web\Response->sendHeaders()
#1 /var/www/task.local/vendor/yiisoft/yii2/web/ErrorHandler.php(135): yii\web\Response->send()
#2 /var/www/task.local/vendor/yiisoft/yii2/base/ErrorHandler.php(111): yii\web\ErrorHandler->renderException(Object(yii\base\ErrorException))
#3 [internal function]: yii\base\ErrorHandler->handleException(Object(yii\base\ErrorException))
#4 {main}
Previous exception:
yii\base\ErrorException: session_set_cookie_params(): Cannot change session cookie parameters when headers already sent in /var/www/task.local/vendor/yiisoft/yii2/web/Session.php:404
Stack trace:
#0 [internal function]: yii\base\ErrorHandler->handleError(2, 'session_set_coo...', '/var/ww" while reading upstream, client: 127.0.0.1, server: task.local.frontend, request: "GET /task HTTP/1.1", upstream: "fastcgi://unix:/var/run/php/php7.2-fpm.sock:", host: "task.local.frontend", referrer: "http://task.local.frontend/"
2019/07/06 00:19:11 [error] 7122#7122: *1 FastCGI sent in stderr: "PHP message: An Error occurred while handling another error:
yii\web\HeadersAlreadySentException: Headers already sent in /var/www/task.local/frontend/controllers/TaskController.php on line 19. in /var/www/task.local/vendor/yiisoft/yii2/web/Response.php:366
Stack trace:
#0 /var/www/task.local/vendor/yiisoft/yii2/web/Response.php(339): yii\web\Response->sendHeaders()
#1 /var/www/task.local/vendor/yiisoft/yii2/web/ErrorHandler.php(135): yii\web\Response->send()
#2 /var/www/task.local/vendor/yiisoft/yii2/base/ErrorHandler.php(111): yii\web\ErrorHandler->renderException(Object(yii\base\ErrorException))
#3 [internal function]: yii\base\ErrorHandler->handleException(Object(yii\base\ErrorException))
#4 {main}
Previous exception:
yii\base\ErrorException: session_set_cookie_params(): Cannot change session cookie parameters when headers already sent in /var/www/task.local/vendor/yiisoft/yii2/web/Session.php:404
Stack trace:
#0 [internal function]: yii\base\ErrorHandler->handleError(2, 'session_set_coo...', '/var/ww" while reading upstream, client: 127.0.0.1, server: task.local.frontend, request: "GET /task HTTP/1.1", upstream: "fastcgi://unix:/var/run/php/php7.2-fpm.sock:", host: "task.local.frontend", referrer: "http://task.local.frontend/"
2019/07/06 00:23:53 [error] 7200#7200: *1 FastCGI sent in stderr: "PHP message: An Error occurred while handling another error:
yii\web\HeadersAlreadySentException: Headers already sent in /var/www/task.local/frontend/controllers/TaskController.php on line 19. in /var/www/task.local/vendor/yiisoft/yii2/web/Response.php:366
Stack trace:
#0 /var/www/task.local/vendor/yiisoft/yii2/web/Response.php(339): yii\web\Response->sendHeaders()
#1 /var/www/task.local/vendor/yiisoft/yii2/web/ErrorHandler.php(135): yii\web\Response->send()
#2 /var/www/task.local/vendor/yiisoft/yii2/base/ErrorHandler.php(111): yii\web\ErrorHandler->renderException(Object(yii\base\ErrorException))
#3 [internal function]: yii\base\ErrorHandler->handleException(Object(yii\base\ErrorException))
#4 {main}
Previous exception:
yii\base\ErrorException: session_set_cookie_params(): Cannot change session cookie parameters when headers already sent in /var/www/task.local/vendor/yiisoft/yii2/web/Session.php:404
Stack trace:
#0 [internal function]: yii\base\ErrorHandler->handleError(2, 'session_set_coo...', '/var/ww" while reading upstream, client: 127.0.0.1, server: task.local.frontend, request: "GET /task HTTP/1.1", upstream: "fastcgi://unix:/var/run/php/php7.2-fpm.sock:", host: "task.local.frontend", referrer: "http://task.local.frontend/"
2019/07/06 00:28:09 [error] 7301#7301: *3 FastCGI sent in stderr: "PHP message: An Error occurred while handling another error:
yii\web\HeadersAlreadySentException: Headers already sent in /var/www/task.local/frontend/controllers/TaskController.php on line 19. in /var/www/task.local/vendor/yiisoft/yii2/web/Response.php:366
Stack trace:
#0 /var/www/task.local/vendor/yiisoft/yii2/web/Response.php(339): yii\web\Response->sendHeaders()
#1 /var/www/task.local/vendor/yiisoft/yii2/web/ErrorHandler.php(135): yii\web\Response->send()
#2 /var/www/task.local/vendor/yiisoft/yii2/base/ErrorHandler.php(111): yii\web\ErrorHandler->renderException(Object(yii\base\ErrorException))
#3 [internal function]: yii\base\ErrorHandler->handleException(Object(yii\base\ErrorException))
#4 {main}
Previous exception:
yii\base\ErrorException: session_set_cookie_params(): Cannot change session cookie parameters when headers already sent in /var/www/task.local/vendor/yiisoft/yii2/web/Session.php:404
Stack trace:
#0 [internal function]: yii\base\ErrorHandler->handleError(2, 'session_set_coo...', '/var/ww" while reading upstream, client: 127.0.0.1, server: task.local.frontend, request: "GET /task HTTP/1.1", upstream: "fastcgi://unix:/var/run/php/php7.2-fpm.sock:", host: "task.local.frontend", referrer: "http://task.local.frontend/"
2019/07/06 00:30:23 [error] 7301#7301: *3 FastCGI sent in stderr: "PHP message: PHP Fatal error:  Cannot use yii\helpers\Url as Url because the name is already in use in /var/www/task.local/frontend/views/task/index.php on line 4" while reading response header from upstream, client: 127.0.0.1, server: task.local.frontend, request: "GET /task HTTP/1.1", upstream: "fastcgi://unix:/var/run/php/php7.2-fpm.sock:", host: "task.local.frontend", referrer: "http://task.local.frontend/"
2019/07/06 01:02:48 [error] 7302#7302: *66 FastCGI sent in stderr: "PHP message: An Error occurred while handling another error:
yii\base\InvalidRouteException: Unable to resolve the request: site/error in /var/www/task.local/vendor/yiisoft/yii2/base/Controller.php:128
Stack trace:
#0 /var/www/task.local/vendor/yiisoft/yii2/base/Module.php(528): yii\base\Controller->runAction('error', Array)
#1 /var/www/task.local/vendor/yiisoft/yii2/web/ErrorHandler.php(108): yii\base\Module->runAction('site/error')
#2 /var/www/task.local/vendor/yiisoft/yii2/base/ErrorHandler.php(111): yii\web\ErrorHandler->renderException(Object(yii\web\NotFoundHttpException))
#3 [internal function]: yii\base\ErrorHandler->handleException(Object(yii\web\NotFoundHttpException))
#4 {main}
Previous exception:
yii\base\InvalidRouteException: Unable to resolve the request "task/index/up". in /var/www/task.local/vendor/yiisoft/yii2/base/Module.php:537
Stack trace:
#0 /var/www/task.local/vendor/yiisoft/yii2/web/Application.php(103): yii\base\Module->runAction('task/index/up', Array)
#1 /var/www/task.local/vend" while reading upstream, client: 127.0.0.1, server: task.local.frontend, request: "GET /task/index/up HTTP/1.1", upstream: "fastcgi://unix:/var/run/php/php7.2-fpm.sock:", host: "task.local.frontend", referrer: "http://task.local.frontend/task"
2019/07/06 01:02:52 [error] 7302#7302: *66 FastCGI sent in stderr: "PHP message: An Error occurred while handling another error:
yii\base\InvalidRouteException: Unable to resolve the request: site/error in /var/www/task.local/vendor/yiisoft/yii2/base/Controller.php:128
Stack trace:
#0 /var/www/task.local/vendor/yiisoft/yii2/base/Module.php(528): yii\base\Controller->runAction('error', Array)
#1 /var/www/task.local/vendor/yiisoft/yii2/web/ErrorHandler.php(108): yii\base\Module->runAction('site/error')
#2 /var/www/task.local/vendor/yiisoft/yii2/base/ErrorHandler.php(111): yii\web\ErrorHandler->renderException(Object(yii\web\NotFoundHttpException))
#3 [internal function]: yii\base\ErrorHandler->handleException(Object(yii\web\NotFoundHttpException))
#4 {main}
Previous exception:
yii\base\InvalidRouteException: Unable to resolve the request "task/index/down". in /var/www/task.local/vendor/yiisoft/yii2/base/Module.php:537
Stack trace:
#0 /var/www/task.local/vendor/yiisoft/yii2/web/Application.php(103): yii\base\Module->runAction('task/index/down', Array)
#1 /var/www/task.local/" while reading upstream, client: 127.0.0.1, server: task.local.frontend, request: "GET /task/index/down HTTP/1.1", upstream: "fastcgi://unix:/var/run/php/php7.2-fpm.sock:", host: "task.local.frontend", referrer: "http://task.local.frontend/task"
2019/07/06 01:03:55 [error] 7302#7302: *66 FastCGI sent in stderr: "PHP message: An Error occurred while handling another error:
yii\base\InvalidRouteException: Unable to resolve the request: site/error in /var/www/task.local/vendor/yiisoft/yii2/base/Controller.php:128
Stack trace:
#0 /var/www/task.local/vendor/yiisoft/yii2/base/Module.php(528): yii\base\Controller->runAction('error', Array)
#1 /var/www/task.local/vendor/yiisoft/yii2/web/ErrorHandler.php(108): yii\base\Module->runAction('site/error')
#2 /var/www/task.local/vendor/yiisoft/yii2/base/ErrorHandler.php(111): yii\web\ErrorHandler->renderException(Object(yii\web\NotFoundHttpException))
#3 [internal function]: yii\base\ErrorHandler->handleException(Object(yii\web\NotFoundHttpException))
#4 {main}
Previous exception:
yii\base\InvalidRouteException: Unable to resolve the request "task/index/up". in /var/www/task.local/vendor/yiisoft/yii2/base/Module.php:537
Stack trace:
#0 /var/www/task.local/vendor/yiisoft/yii2/web/Application.php(103): yii\base\Module->runAction('task/index/up', Array)
#1 /var/www/task.local/vend" while reading upstream, client: 127.0.0.1, server: task.local.frontend, request: "GET /task/index/up HTTP/1.1", upstream: "fastcgi://unix:/var/run/php/php7.2-fpm.sock:", host: "task.local.frontend", referrer: "http://task.local.frontend/task"
2019/07/06 01:04:23 [error] 7302#7302: *66 FastCGI sent in stderr: "PHP message: An Error occurred while handling another error:
yii\base\InvalidRouteException: Unable to resolve the request: site/error in /var/www/task.local/vendor/yiisoft/yii2/base/Controller.php:128
Stack trace:
#0 /var/www/task.local/vendor/yiisoft/yii2/base/Module.php(528): yii\base\Controller->runAction('error', Array)
#1 /var/www/task.local/vendor/yiisoft/yii2/web/ErrorHandler.php(108): yii\base\Module->runAction('site/error')
#2 /var/www/task.local/vendor/yiisoft/yii2/base/ErrorHandler.php(111): yii\web\ErrorHandler->renderException(Object(yii\web\NotFoundHttpException))
#3 [internal function]: yii\base\ErrorHandler->handleException(Object(yii\web\NotFoundHttpException))
#4 {main}
Previous exception:
yii\base\InvalidRouteException: Unable to resolve the request "task/index/up". in /var/www/task.local/vendor/yiisoft/yii2/base/Module.php:537
Stack trace:
#0 /var/www/task.local/vendor/yiisoft/yii2/web/Application.php(103): yii\base\Module->runAction('task/index/up', Array)
#1 /var/www/task.local/vend" while reading upstream, client: 127.0.0.1, server: task.local.frontend, request: "GET /task/index/up HTTP/1.1", upstream: "fastcgi://unix:/var/run/php/php7.2-fpm.sock:", host: "task.local.frontend", referrer: "http://task.local.frontend/task"
2019/07/06 01:04:57 [error] 7302#7302: *66 FastCGI sent in stderr: "PHP message: An Error occurred while handling another error:
yii\base\InvalidRouteException: Unable to resolve the request: site/error in /var/www/task.local/vendor/yiisoft/yii2/base/Controller.php:128
Stack trace:
#0 /var/www/task.local/vendor/yiisoft/yii2/base/Module.php(528): yii\base\Controller->runAction('error', Array)
#1 /var/www/task.local/vendor/yiisoft/yii2/web/ErrorHandler.php(108): yii\base\Module->runAction('site/error')
#2 /var/www/task.local/vendor/yiisoft/yii2/base/ErrorHandler.php(111): yii\web\ErrorHandler->renderException(Object(yii\web\NotFoundHttpException))
#3 [internal function]: yii\base\ErrorHandler->handleException(Object(yii\web\NotFoundHttpException))
#4 {main}
Previous exception:
yii\base\InvalidRouteException: Unable to resolve the request "task/index/down". in /var/www/task.local/vendor/yiisoft/yii2/base/Module.php:537
Stack trace:
#0 /var/www/task.local/vendor/yiisoft/yii2/web/Application.php(103): yii\base\Module->runAction('task/index/down', Array)
#1 /var/www/task.local/" while reading upstream, client: 127.0.0.1, server: task.local.frontend, request: "GET /task/index/down HTTP/1.1", upstream: "fastcgi://unix:/var/run/php/php7.2-fpm.sock:", host: "task.local.frontend", referrer: "http://task.local.frontend/task"
2019/07/06 01:07:15 [error] 7301#7301: *79 FastCGI sent in stderr: "PHP message: An Error occurred while handling another error:
yii\base\InvalidRouteException: Unable to resolve the request: site/error in /var/www/task.local/vendor/yiisoft/yii2/base/Controller.php:128
Stack trace:
#0 /var/www/task.local/vendor/yiisoft/yii2/base/Module.php(528): yii\base\Controller->runAction('error', Array)
#1 /var/www/task.local/vendor/yiisoft/yii2/web/ErrorHandler.php(108): yii\base\Module->runAction('site/error')
#2 /var/www/task.local/vendor/yiisoft/yii2/base/ErrorHandler.php(111): yii\web\ErrorHandler->renderException(Object(yii\web\NotFoundHttpException))
#3 [internal function]: yii\base\ErrorHandler->handleException(Object(yii\web\NotFoundHttpException))
#4 {main}
Previous exception:
yii\base\InvalidRouteException: Unable to resolve the request "task/index/up". in /var/www/task.local/vendor/yiisoft/yii2/base/Module.php:537
Stack trace:
#0 /var/www/task.local/vendor/yiisoft/yii2/web/Application.php(103): yii\base\Module->runAction('task/index/up', Array)
#1 /var/www/task.local/vend" while reading upstream, client: 127.0.0.1, server: task.local.frontend, request: "GET /task/index/up HTTP/1.1", upstream: "fastcgi://unix:/var/run/php/php7.2-fpm.sock:", host: "task.local.frontend", referrer: "http://task.local.frontend/task"
2019/07/06 01:08:10 [error] 7301#7301: *79 FastCGI sent in stderr: "PHP message: An Error occurred while handling another error:
yii\base\InvalidRouteException: Unable to resolve the request: site/error in /var/www/task.local/vendor/yiisoft/yii2/base/Controller.php:128
Stack trace:
#0 /var/www/task.local/vendor/yiisoft/yii2/base/Module.php(528): yii\base\Controller->runAction('error', Array)
#1 /var/www/task.local/vendor/yiisoft/yii2/web/ErrorHandler.php(108): yii\base\Module->runAction('site/error')
#2 /var/www/task.local/vendor/yiisoft/yii2/base/ErrorHandler.php(111): yii\web\ErrorHandler->renderException(Object(yii\web\NotFoundHttpException))
#3 [internal function]: yii\base\ErrorHandler->handleException(Object(yii\web\NotFoundHttpException))
#4 {main}
Previous exception:
yii\base\InvalidRouteException: Unable to resolve the request "task/index/up". in /var/www/task.local/vendor/yiisoft/yii2/base/Module.php:537
Stack trace:
#0 /var/www/task.local/vendor/yiisoft/yii2/web/Application.php(103): yii\base\Module->runAction('task/index/up', Array)
#1 /var/www/task.local/vend" while reading upstream, client: 127.0.0.1, server: task.local.frontend, request: "GET /task/index/up HTTP/1.1", upstream: "fastcgi://unix:/var/run/php/php7.2-fpm.sock:", host: "task.local.frontend", referrer: "http://task.local.frontend/task"
2019/07/06 01:18:25 [error] 7301#7301: *94 FastCGI sent in stderr: "PHP message: An Error occurred while handling another error:
yii\base\InvalidRouteException: Unable to resolve the request: site/error in /var/www/task.local/vendor/yiisoft/yii2/base/Controller.php:128
Stack trace:
#0 /var/www/task.local/vendor/yiisoft/yii2/base/Module.php(528): yii\base\Controller->runAction('error', Array)
#1 /var/www/task.local/vendor/yiisoft/yii2/web/ErrorHandler.php(108): yii\base\Module->runAction('site/error')
#2 /var/www/task.local/vendor/yiisoft/yii2/base/ErrorHandler.php(111): yii\web\ErrorHandler->renderException(Object(yii\web\NotFoundHttpException))
#3 [internal function]: yii\base\ErrorHandler->handleException(Object(yii\web\NotFoundHttpException))
#4 {main}
Previous exception:
yii\base\InvalidRouteException: Unable to resolve the request: task/downd in /var/www/task.local/vendor/yiisoft/yii2/base/Controller.php:128
Stack trace:
#0 /var/www/task.local/vendor/yiisoft/yii2/base/Module.php(528): yii\base\Controller->runAction('downd', Array)
#1 /var/www/task.local/vendor/yiisof" while reading upstream, client: 127.0.0.1, server: task.local.frontend, request: "GET /task/downd HTTP/1.1", upstream: "fastcgi://unix:/var/run/php/php7.2-fpm.sock:", host: "task.local.frontend"
2019/07/06 01:18:36 [error] 7301#7301: *94 FastCGI sent in stderr: "PHP message: An Error occurred while handling another error:
yii\base\InvalidRouteException: Unable to resolve the request: site/error in /var/www/task.local/vendor/yiisoft/yii2/base/Controller.php:128
Stack trace:
#0 /var/www/task.local/vendor/yiisoft/yii2/base/Module.php(528): yii\base\Controller->runAction('error', Array)
#1 /var/www/task.local/vendor/yiisoft/yii2/web/ErrorHandler.php(108): yii\base\Module->runAction('site/error')
#2 /var/www/task.local/vendor/yiisoft/yii2/base/ErrorHandler.php(111): yii\web\ErrorHandler->renderException(Object(yii\web\NotFoundHttpException))
#3 [internal function]: yii\base\ErrorHandler->handleException(Object(yii\web\NotFoundHttpException))
#4 {main}
Previous exception:
yii\base\InvalidRouteException: Unable to resolve the request: task/downdown in /var/www/task.local/vendor/yiisoft/yii2/base/Controller.php:128
Stack trace:
#0 /var/www/task.local/vendor/yiisoft/yii2/base/Module.php(528): yii\base\Controller->runAction('downdown', Array)
#1 /var/www/task.local/vendor/" while reading upstream, client: 127.0.0.1, server: task.local.frontend, request: "GET /task/downdown HTTP/1.1", upstream: "fastcgi://unix:/var/run/php/php7.2-fpm.sock:", host: "task.local.frontend"
2019/07/07 21:59:00 [error] 3766#3766: *42 FastCGI sent in stderr: "PHP message: An Error occurred while handling another error:
yii\base\InvalidRouteException: Unable to resolve the request: site/error in /var/www/task.local/vendor/yiisoft/yii2/base/Controller.php:128
Stack trace:
#0 /var/www/task.local/vendor/yiisoft/yii2/base/Module.php(528): yii\base\Controller->runAction('error', Array)
#1 /var/www/task.local/vendor/yiisoft/yii2/web/ErrorHandler.php(108): yii\base\Module->runAction('site/error')
#2 /var/www/task.local/vendor/yiisoft/yii2/base/ErrorHandler.php(111): yii\web\ErrorHandler->renderException(Object(yii\web\NotFoundHttpException))
#3 [internal function]: yii\base\ErrorHandler->handleException(Object(yii\web\NotFoundHttpException))
#4 {main}
Previous exception:
yii\base\InvalidRouteException: Unable to resolve the request "task/delete/7". in /var/www/task.local/vendor/yiisoft/yii2/base/Module.php:537
Stack trace:
#0 /var/www/task.local/vendor/yiisoft/yii2/web/Application.php(103): yii\base\Module->runAction('task/delete/7', Array)
#1 /var/www/task.local/vend" while reading upstream, client: 127.0.0.1, server: task.local.frontend, request: "GET /task/delete/7 HTTP/1.1", upstream: "fastcgi://unix:/var/run/php/php7.2-fpm.sock:", host: "task.local.frontend", referrer: "http://task.local.frontend/task"
2019/07/07 21:59:53 [error] 3766#3766: *44 FastCGI sent in stderr: "PHP message: An Error occurred while handling another error:
yii\base\InvalidRouteException: Unable to resolve the request: site/error in /var/www/task.local/vendor/yiisoft/yii2/base/Controller.php:128
Stack trace:
#0 /var/www/task.local/vendor/yiisoft/yii2/base/Module.php(528): yii\base\Controller->runAction('error', Array)
#1 /var/www/task.local/vendor/yiisoft/yii2/web/ErrorHandler.php(108): yii\base\Module->runAction('site/error')
#2 /var/www/task.local/vendor/yiisoft/yii2/base/ErrorHandler.php(111): yii\web\ErrorHandler->renderException(Object(yii\web\NotFoundHttpException))
#3 [internal function]: yii\base\ErrorHandler->handleException(Object(yii\web\NotFoundHttpException))
#4 {main}
Previous exception:
yii\base\InvalidRouteException: Unable to resolve the request "task/delete/7". in /var/www/task.local/vendor/yiisoft/yii2/base/Module.php:537
Stack trace:
#0 /var/www/task.local/vendor/yiisoft/yii2/web/Application.php(103): yii\base\Module->runAction('task/delete/7', Array)
#1 /var/www/task.local/vend" while reading upstream, client: 127.0.0.1, server: task.local.frontend, request: "GET /task/delete/7 HTTP/1.1", upstream: "fastcgi://unix:/var/run/php/php7.2-fpm.sock:", host: "task.local.frontend", referrer: "http://task.local.frontend/task"
2019/07/07 22:00:36 [error] 3766#3766: *44 FastCGI sent in stderr: "PHP message: An Error occurred while handling another error:
yii\base\InvalidRouteException: Unable to resolve the request: site/error in /var/www/task.local/vendor/yiisoft/yii2/base/Controller.php:128
Stack trace:
#0 /var/www/task.local/vendor/yiisoft/yii2/base/Module.php(528): yii\base\Controller->runAction('error', Array)
#1 /var/www/task.local/vendor/yiisoft/yii2/web/ErrorHandler.php(108): yii\base\Module->runAction('site/error')
#2 /var/www/task.local/vendor/yiisoft/yii2/base/ErrorHandler.php(111): yii\web\ErrorHandler->renderException(Object(yii\web\BadRequestHttpException))
#3 [internal function]: yii\base\ErrorHandler->handleException(Object(yii\web\BadRequestHttpException))
#4 {main}
Previous exception:
yii\web\BadRequestHttpException: Отсутствуют обязательные параметры: id in /var/www/task.local/vendor/yiisoft/yii2/web/Controller.php:149
Stack trace:
#0 /var/www/task.local/vendor/yiisoft/yii2/base/InlineAction.php(51): yii\web\Controller->bindActionParams(Object(y" while reading upstream, client: 127.0.0.1, server: task.local.frontend, request: "GET /task/delete/7 HTTP/1.1", upstream: "fastcgi://unix:/var/run/php/php7.2-fpm.sock:", host: "task.local.frontend", referrer: "http://task.local.frontend/task"
2019/07/07 22:01:57 [error] 3766#3766: *49 FastCGI sent in stderr: "PHP message: An Error occurred while handling another error:
yii\base\InvalidRouteException: Unable to resolve the request: site/error in /var/www/task.local/vendor/yiisoft/yii2/base/Controller.php:128
Stack trace:
#0 /var/www/task.local/vendor/yiisoft/yii2/base/Module.php(528): yii\base\Controller->runAction('error', Array)
#1 /var/www/task.local/vendor/yiisoft/yii2/web/ErrorHandler.php(108): yii\base\Module->runAction('site/error')
#2 /var/www/task.local/vendor/yiisoft/yii2/base/ErrorHandler.php(111): yii\web\ErrorHandler->renderException(Object(yii\web\BadRequestHttpException))
#3 [internal function]: yii\base\ErrorHandler->handleException(Object(yii\web\BadRequestHttpException))
#4 {main}
Previous exception:
yii\web\BadRequestHttpException: Отсутствуют обязательные параметры: id in /var/www/task.local/vendor/yiisoft/yii2/web/Controller.php:149
Stack trace:
#0 /var/www/task.local/vendor/yiisoft/yii2/base/InlineAction.php(51): yii\web\Controller->bindActionParams(Object(y" while reading upstream, client: 127.0.0.1, server: task.local.frontend, request: "GET /task/delete/7 HTTP/1.1", upstream: "fastcgi://unix:/var/run/php/php7.2-fpm.sock:", host: "task.local.frontend", referrer: "http://task.local.frontend/task"
2019/07/07 22:02:34 [error] 3766#3766: *49 FastCGI sent in stderr: "PHP message: An Error occurred while handling another error:
yii\base\InvalidRouteException: Unable to resolve the request: site/error in /var/www/task.local/vendor/yiisoft/yii2/base/Controller.php:128
Stack trace:
#0 /var/www/task.local/vendor/yiisoft/yii2/base/Module.php(528): yii\base\Controller->runAction('error', Array)
#1 /var/www/task.local/vendor/yiisoft/yii2/web/ErrorHandler.php(108): yii\base\Module->runAction('site/error')
#2 /var/www/task.local/vendor/yiisoft/yii2/base/ErrorHandler.php(111): yii\web\ErrorHandler->renderException(Object(yii\web\NotFoundHttpException))
#3 [internal function]: yii\base\ErrorHandler->handleException(Object(yii\web\NotFoundHttpException))
#4 {main}
Previous exception:
yii\base\InvalidRouteException: Unable to resolve the request "task/delete/7". in /var/www/task.local/vendor/yiisoft/yii2/base/Module.php:537
Stack trace:
#0 /var/www/task.local/vendor/yiisoft/yii2/web/Application.php(103): yii\base\Module->runAction('task/delete/7', Array)
#1 /var/www/task.local/vend" while reading upstream, client: 127.0.0.1, server: task.local.frontend, request: "GET /task/delete/7 HTTP/1.1", upstream: "fastcgi://unix:/var/run/php/php7.2-fpm.sock:", host: "task.local.frontend", referrer: "http://task.local.frontend/task"
2019/07/07 22:03:02 [error] 3766#3766: *49 FastCGI sent in stderr: "PHP message: An Error occurred while handling another error:
yii\base\InvalidRouteException: Unable to resolve the request: site/error in /var/www/task.local/vendor/yiisoft/yii2/base/Controller.php:128
Stack trace:
#0 /var/www/task.local/vendor/yiisoft/yii2/base/Module.php(528): yii\base\Controller->runAction('error', Array)
#1 /var/www/task.local/vendor/yiisoft/yii2/web/ErrorHandler.php(108): yii\base\Module->runAction('site/error')
#2 /var/www/task.local/vendor/yiisoft/yii2/base/ErrorHandler.php(111): yii\web\ErrorHandler->renderException(Object(yii\web\BadRequestHttpException))
#3 [internal function]: yii\base\ErrorHandler->handleException(Object(yii\web\BadRequestHttpException))
#4 {main}
Previous exception:
yii\web\BadRequestHttpException: Отсутствуют обязательные параметры: id in /var/www/task.local/vendor/yiisoft/yii2/web/Controller.php:149
Stack trace:
#0 /var/www/task.local/vendor/yiisoft/yii2/base/InlineAction.php(51): yii\web\Controller->bindActionParams(Object(y" while reading upstream, client: 127.0.0.1, server: task.local.frontend, request: "GET /task/delete/7 HTTP/1.1", upstream: "fastcgi://unix:/var/run/php/php7.2-fpm.sock:", host: "task.local.frontend", referrer: "http://task.local.frontend/task"
